Workbook

Sheet Expiries
M1: START HERE | N1: 1. Paste INDEX SHARES into column B and the INDEX DIVISOR into B3 on the AS51 and MXAU tabs (blue).
B2: CONTRACT EXPIRY CALENDAR - MASTER CONTROL | N2: 2. Set the two inputs below, then refresh on a Bloomberg terminal (Ctrl+Alt+F9).
B3: Everything downstream keys off this tab. Change the two inputs here, nothing else. | N3: 3. Read Div by Expiry for the dividend points and spreads; Futures FV to price a contract; Override to put your own numbers in.
B5: INPUTS
B6: Valuation date | C6: =TODAY() | N6: Today by default. Type a date to freeze the study.
B7: Contracts to build | C7: 13 | N7: 13 = a full year of monthly expiries. Max 16.
B9: AUTO
B10: First contract month | C10: =IF(DATE(YEAR($C$6),MONTH($C$6),1)+MOD(5-WEEKDAY(DATE(YEAR($C$6),MONTH($C$6),1),1)+7,7)+14>=$C$6,DATE(YEAR($C$6),MONTH($C$6),1),EDATE(DATE(YEAR($C$6),MONTH($C$6),1),1)) | N10: Rolls to the next month once the front expiry has passed.
B11: Projections run to | C11: ='Dvd Calendar'!$K$3 | N11: Last projected ex-date found in the data. Contracts expiring after it are flagged CHECK.
B12: Contracts covered | C12: =COUNTIF($L$16:$L$31,"OK")
B13: Contracts flagged CHECK | C13: =COUNTIF($L$16:$L$31,"CHECK") | N13: CHECK = Bloomberg's projections stop before that expiry, so its dividends are understated.
B15: # | C15: Contract | D15: AS51 expiry (auto 3rd Thu) | E15: Override | F15: AS51 EXPIRY | G15: MXAU expiry (auto 3rd Fri) | H15: Override | I15: MXAU EXPIRY | J15: AS51 window start | K15: MXAU window start | L15: Covered? | N15: Blue cells are optional. Fill one only if your contract expires on a different day.
B16: =IF(1>$C$7,"",1) | C16: =IF($B16="","",UPPER(TEXT(EDATE($C$10,$B16-1),"mmmyy"))) | D16: =IF($B16="","",EDATE($C$10,$B16-1)+MOD(5-WEEKDAY(EDATE($C$10,$B16-1),1)+7,7)+14) | F16: =IF($B16="","",IF($E16="",$D16,$E16)) | G16: =IF($B16="","",EDATE($C$10,$B16-1)+MOD(6-WEEKDAY(EDATE($C$10,$B16-1),1)+7,7)+14) | I16: =IF($B16="","",IF($H16="",$G16,$H16)) | J16: =IF($B16="","",IF($B16=1,$C$6,$F15)) | K16: =IF($B16="","",IF($B16=1,$C$6,$I15)) | L16: =IF($B16="","",IF($C$11="","CHECK",IF($F16<=$C$11,"OK","CHECK")))
B17: =IF(2>$C$7,"",2) | C17: =IF($B17="","",UPPER(TEXT(EDATE($C$10,$B17-1),"mmmyy"))) | D17: =IF($B17="","",EDATE($C$10,$B17-1)+MOD(5-WEEKDAY(EDATE($C$10,$B17-1),1)+7,7)+14) | F17: =IF($B17="","",IF($E17="",$D17,$E17)) | G17: =IF($B17="","",EDATE($C$10,$B17-1)+MOD(6-WEEKDAY(EDATE($C$10,$B17-1),1)+7,7)+14) | I17: =IF($B17="","",IF($H17="",$G17,$H17)) | J17: =IF($B17="","",IF($B17=1,$C$6,$F16)) | K17: =IF($B17="","",IF($B17=1,$C$6,$I16)) | L17: =IF($B17="","",IF($C$11="","CHECK",IF($F17<=$C$11,"OK","CHECK")))
B18: =IF(3>$C$7,"",3) | C18: =IF($B18="","",UPPER(TEXT(EDATE($C$10,$B18-1),"mmmyy"))) | D18: =IF($B18="","",EDATE($C$10,$B18-1)+MOD(5-WEEKDAY(EDATE($C$10,$B18-1),1)+7,7)+14) | F18: =IF($B18="","",IF($E18="",$D18,$E18)) | G18: =IF($B18="","",EDATE($C$10,$B18-1)+MOD(6-WEEKDAY(EDATE($C$10,$B18-1),1)+7,7)+14) | I18: =IF($B18="","",IF($H18="",$G18,$H18)) | J18: =IF($B18="","",IF($B18=1,$C$6,$F17)) | K18: =IF($B18="","",IF($B18=1,$C$6,$I17)) | L18: =IF($B18="","",IF($C$11="","CHECK",IF($F18<=$C$11,"OK","CHECK")))
B19: =IF(4>$C$7,"",4) | C19: =IF($B19="","",UPPER(TEXT(EDATE($C$10,$B19-1),"mmmyy"))) | D19: =IF($B19="","",EDATE($C$10,$B19-1)+MOD(5-WEEKDAY(EDATE($C$10,$B19-1),1)+7,7)+14) | F19: =IF($B19="","",IF($E19="",$D19,$E19)) | G19: =IF($B19="","",EDATE($C$10,$B19-1)+MOD(6-WEEKDAY(EDATE($C$10,$B19-1),1)+7,7)+14) | I19: =IF($B19="","",IF($H19="",$G19,$H19)) | J19: =IF($B19="","",IF($B19=1,$C$6,$F18)) | K19: =IF($B19="","",IF($B19=1,$C$6,$I18)) | L19: =IF($B19="","",IF($C$11="","CHECK",IF($F19<=$C$11,"OK","CHECK")))
B20: =IF(5>$C$7,"",5) | C20: =IF($B20="","",UPPER(TEXT(EDATE($C$10,$B20-1),"mmmyy"))) | D20: =IF($B20="","",EDATE($C$10,$B20-1)+MOD(5-WEEKDAY(EDATE($C$10,$B20-1),1)+7,7)+14) | F20: =IF($B20="","",IF($E20="",$D20,$E20)) | G20: =IF($B20="","",EDATE($C$10,$B20-1)+MOD(6-WEEKDAY(EDATE($C$10,$B20-1),1)+7,7)+14) | I20: =IF($B20="","",IF($H20="",$G20,$H20)) | J20: =IF($B20="","",IF($B20=1,$C$6,$F19)) | K20: =IF($B20="","",IF($B20=1,$C$6,$I19)) | L20: =IF($B20="","",IF($C$11="","CHECK",IF($F20<=$C$11,"OK","CHECK")))
B21: =IF(6>$C$7,"",6) | C21: =IF($B21="","",UPPER(TEXT(EDATE($C$10,$B21-1),"mmmyy"))) | D21: =IF($B21="","",EDATE($C$10,$B21-1)+MOD(5-WEEKDAY(EDATE($C$10,$B21-1),1)+7,7)+14) | F21: =IF($B21="","",IF($E21="",$D21,$E21)) | G21: =IF($B21="","",EDATE($C$10,$B21-1)+MOD(6-WEEKDAY(EDATE($C$10,$B21-1),1)+7,7)+14) | I21: =IF($B21="","",IF($H21="",$G21,$H21)) | J21: =IF($B21="","",IF($B21=1,$C$6,$F20)) | K21: =IF($B21="","",IF($B21=1,$C$6,$I20)) | L21: =IF($B21="","",IF($C$11="","CHECK",IF($F21<=$C$11,"OK","CHECK")))
B22: =IF(7>$C$7,"",7) | C22: =IF($B22="","",UPPER(TEXT(EDATE($C$10,$B22-1),"mmmyy"))) | D22: =IF($B22="","",EDATE($C$10,$B22-1)+MOD(5-WEEKDAY(EDATE($C$10,$B22-1),1)+7,7)+14) | F22: =IF($B22="","",IF($E22="",$D22,$E22)) | G22: =IF($B22="","",EDATE($C$10,$B22-1)+MOD(6-WEEKDAY(EDATE($C$10,$B22-1),1)+7,7)+14) | I22: =IF($B22="","",IF($H22="",$G22,$H22)) | J22: =IF($B22="","",IF($B22=1,$C$6,$F21)) | K22: =IF($B22="","",IF($B22=1,$C$6,$I21)) | L22: =IF($B22="","",IF($C$11="","CHECK",IF($F22<=$C$11,"OK","CHECK")))
B23: =IF(8>$C$7,"",8) | C23: =IF($B23="","",UPPER(TEXT(EDATE($C$10,$B23-1),"mmmyy"))) | D23: =IF($B23="","",EDATE($C$10,$B23-1)+MOD(5-WEEKDAY(EDATE($C$10,$B23-1),1)+7,7)+14) | F23: =IF($B23="","",IF($E23="",$D23,$E23)) | G23: =IF($B23="","",EDATE($C$10,$B23-1)+MOD(6-WEEKDAY(EDATE($C$10,$B23-1),1)+7,7)+14) | I23: =IF($B23="","",IF($H23="",$G23,$H23)) | J23: =IF($B23="","",IF($B23=1,$C$6,$F22)) | K23: =IF($B23="","",IF($B23=1,$C$6,$I22)) | L23: =IF($B23="","",IF($C$11="","CHECK",IF($F23<=$C$11,"OK","CHECK")))
B24: =IF(9>$C$7,"",9) | C24: =IF($B24="","",UPPER(TEXT(EDATE($C$10,$B24-1),"mmmyy"))) | D24: =IF($B24="","",EDATE($C$10,$B24-1)+MOD(5-WEEKDAY(EDATE($C$10,$B24-1),1)+7,7)+14) | F24: =IF($B24="","",IF($E24="",$D24,$E24)) | G24: =IF($B24="","",EDATE($C$10,$B24-1)+MOD(6-WEEKDAY(EDATE($C$10,$B24-1),1)+7,7)+14) | I24: =IF($B24="","",IF($H24="",$G24,$H24)) | J24: =IF($B24="","",IF($B24=1,$C$6,$F23)) | K24: =IF($B24="","",IF($B24=1,$C$6,$I23)) | L24: =IF($B24="","",IF($C$11="","CHECK",IF($F24<=$C$11,"OK","CHECK")))
B25: =IF(10>$C$7,"",10) | C25: =IF($B25="","",UPPER(TEXT(EDATE($C$10,$B25-1),"mmmyy"))) | D25: =IF($B25="","",EDATE($C$10,$B25-1)+MOD(5-WEEKDAY(EDATE($C$10,$B25-1),1)+7,7)+14) | F25: =IF($B25="","",IF($E25="",$D25,$E25)) | G25: =IF($B25="","",EDATE($C$10,$B25-1)+MOD(6-WEEKDAY(EDATE($C$10,$B25-1),1)+7,7)+14) | I25: =IF($B25="","",IF($H25="",$G25,$H25)) | J25: =IF($B25="","",IF($B25=1,$C$6,$F24)) | K25: =IF($B25="","",IF($B25=1,$C$6,$I24)) | L25: =IF($B25="","",IF($C$11="","CHECK",IF($F25<=$C$11,"OK","CHECK")))
B26: =IF(11>$C$7,"",11) | C26: =IF($B26="","",UPPER(TEXT(EDATE($C$10,$B26-1),"mmmyy"))) | D26: =IF($B26="","",EDATE($C$10,$B26-1)+MOD(5-WEEKDAY(EDATE($C$10,$B26-1),1)+7,7)+14) | F26: =IF($B26="","",IF($E26="",$D26,$E26)) | G26: =IF($B26="","",EDATE($C$10,$B26-1)+MOD(6-WEEKDAY(EDATE($C$10,$B26-1),1)+7,7)+14) | I26: =IF($B26="","",IF($H26="",$G26,$H26)) | J26: =IF($B26="","",IF($B26=1,$C$6,$F25)) | K26: =IF($B26="","",IF($B26=1,$C$6,$I25)) | L26: =IF($B26="","",IF($C$11="","CHECK",IF($F26<=$C$11,"OK","CHECK")))
B27: =IF(12>$C$7,"",12) | C27: =IF($B27="","",UPPER(TEXT(EDATE($C$10,$B27-1),"mmmyy"))) | D27: =IF($B27="","",EDATE($C$10,$B27-1)+MOD(5-WEEKDAY(EDATE($C$10,$B27-1),1)+7,7)+14) | F27: =IF($B27="","",IF($E27="",$D27,$E27)) | G27: =IF($B27="","",EDATE($C$10,$B27-1)+MOD(6-WEEKDAY(EDATE($C$10,$B27-1),1)+7,7)+14) | I27: =IF($B27="","",IF($H27="",$G27,$H27)) | J27: =IF($B27="","",IF($B27=1,$C$6,$F26)) | K27: =IF($B27="","",IF($B27=1,$C$6,$I26)) | L27: =IF($B27="","",IF($C$11="","CHECK",IF($F27<=$C$11,"OK","CHECK")))
B28: =IF(13>$C$7,"",13) | C28: =IF($B28="","",UPPER(TEXT(EDATE($C$10,$B28-1),"mmmyy"))) | D28: =IF($B28="","",EDATE($C$10,$B28-1)+MOD(5-WEEKDAY(EDATE($C$10,$B28-1),1)+7,7)+14) | F28: =IF($B28="","",IF($E28="",$D28,$E28)) | G28: =IF($B28="","",EDATE($C$10,$B28-1)+MOD(6-WEEKDAY(EDATE($C$10,$B28-1),1)+7,7)+14) | I28: =IF($B28="","",IF($H28="",$G28,$H28)) | J28: =IF($B28="","",IF($B28=1,$C$6,$F27)) | K28: =IF($B28="","",IF($B28=1,$C$6,$I27)) | L28: =IF($B28="","",IF($C$11="","CHECK",IF($F28<=$C$11,"OK","CHECK")))
B29: =IF(14>$C$7,"",14) | C29: =IF($B29="","",UPPER(TEXT(EDATE($C$10,$B29-1),"mmmyy"))) | D29: =IF($B29="","",EDATE($C$10,$B29-1)+MOD(5-WEEKDAY(EDATE($C$10,$B29-1),1)+7,7)+14) | F29: =IF($B29="","",IF($E29="",$D29,$E29)) | G29: =IF($B29="","",EDATE($C$10,$B29-1)+MOD(6-WEEKDAY(EDATE($C$10,$B29-1),1)+7,7)+14) | I29: =IF($B29="","",IF($H29="",$G29,$H29)) | J29: =IF($B29="","",IF($B29=1,$C$6,$F28)) | K29: =IF($B29="","",IF($B29=1,$C$6,$I28)) | L29: =IF($B29="","",IF($C$11="","CHECK",IF($F29<=$C$11,"OK","CHECK")))
B30: =IF(15>$C$7,"",15) | C30: =IF($B30="","",UPPER(TEXT(EDATE($C$10,$B30-1),"mmmyy"))) | D30: =IF($B30="","",EDATE($C$10,$B30-1)+MOD(5-WEEKDAY(EDATE($C$10,$B30-1),1)+7,7)+14) | F30: =IF($B30="","",IF($E30="",$D30,$E30)) | G30: =IF($B30="","",EDATE($C$10,$B30-1)+MOD(6-WEEKDAY(EDATE($C$10,$B30-1),1)+7,7)+14) | I30: =IF($B30="","",IF($H30="",$G30,$H30)) | J30: =IF($B30="","",IF($B30=1,$C$6,$F29)) | K30: =IF($B30="","",IF($B30=1,$C$6,$I29)) | L30: =IF($B30="","",IF($C$11="","CHECK",IF($F30<=$C$11,"OK","CHECK")))
B31: =IF(16>$C$7,"",16) | C31: =IF($B31="","",UPPER(TEXT(EDATE($C$10,$B31-1),"mmmyy"))) | D31: =IF($B31="","",EDATE($C$10,$B31-1)+MOD(5-WEEKDAY(EDATE($C$10,$B31-1),1)+7,7)+14) | F31: =IF($B31="","",IF($E31="",$D31,$E31)) | G31: =IF($B31="","",EDATE($C$10,$B31-1)+MOD(6-WEEKDAY(EDATE($C$10,$B31-1),1)+7,7)+14) | I31: =IF($B31="","",IF($H31="",$G31,$H31)) | J31: =IF($B31="","",IF($B31=1,$C$6,$F30)) | K31: =IF($B31="","",IF($B31=1,$C$6,$I30)) | L31: =IF($B31="","",IF($C$11="","CHECK",IF($F31<=$C$11,"OK","CHECK")))
B33: Window | C33: A contract holds the dividends with an ex-date after the previous expiry and on or before its own. The front contract's window opens on the valuation date, so it carries only what is still to come.

Sheet Div by Expiry
B2: INDEX DIVIDEND BY FUTURES EXPIRY
B3: Projected dividends bucketed into each contract window - index points, yield and annualized yield, both indices, and the spread between them.
B5: AS51 index level | C5: =_xll.BDP('AS51'!$B$2,"LAST_PRICE") | E5: MXAU is quoted in USD, so its points are USD points. Yields and the bps spreads are currency-consistent - each index is divided by its own level.
B6: MXAU index level | C6: =_xll.BDP(MXAU!$B$2,"LAST_PRICE") | E6: Everything here is Bloomberg's BDVD projection (plus your overrides when ON). Covered? flags contracts past the projected horizon.
B7: Valuation date | C7: =Expiries!$C$6 | E7: Ann. = cum yield x 365 / days to that expiry (ACT/365, per leg). The front contract divides by only a few days - noisy, read with care.
B8: Projections run to | C8: =Expiries!$C$11
B9: Overrides | C9: =IF(Override!$C$4="ON","ON - "&Override!$E$4&" row(s) live - Accrual uses YOUR numbers where set (Override tab).","OFF - pure Bloomberg projections.")
E11: S&P/ASX 200 (AS51) | K11: MSCI AUSTRALIA (MXAU) | P11: SPREAD
B12: Contract | C12: Expiry | D12: Days | E12: Period DPS (pts) | F12: Period yld (%) | G12: Cum DPS (pts) | H12: Cum yld (%) | I12: Ann cum yld (%) | J12: Expiry | K12: Period DPS (pts) | L12: Period yld (%) | M12: Cum DPS (pts) | N12: Cum yld (%) | O12: Ann cum yld (%) | P12: AS51-MXAU cum (bps) | Q12: Ann sprd (bps) | R12: Covered?
B13: =IF(Expiries!$B16="","",Expiries!$C16) | C13: =IF($B13="","",Expiries!$F16) | D13: =IF($B13="","",$C13-$C$7) | E13: =IF($B13="","",IFERROR(Accrual!F$221,"")) | F13: =IF($B13="","",IFERROR($E13/$C$5,"")) | G13: =IF($B13="","",SUM($E$13:$E13)) | H13: =IF($B13="","",IFERROR($G13/$C$5,"")) | I13: =IF($B13="","",IFERROR($H13*365/$D13,"")) | J13: =IF($B13="","",Expiries!$I16) | K13: =IF($B13="","",IFERROR(Accrual!F$309,"")) | L13: =IF($B13="","",IFERROR($K13/$C$6,"")) | M13: =IF($B13="","",SUM($K$13:$K13)) | N13: =IF($B13="","",IFERROR($M13/$C$6,"")) | O13: =IF($B13="","",IFERROR($N13*365/($J13-$C$7),"")) | P13: =IF($B13="","",IFERROR(($H13-$N13)*10000,"")) | Q13: =IF($B13="","",IFERROR(($I13-$O13)*10000,"")) | R13: =IF($B13="","",Expiries!$L16)
B14: =IF(Expiries!$B17="","",Expiries!$C17) | C14: =IF($B14="","",Expiries!$F17) | D14: =IF($B14="","",$C14-$C$7) | E14: =IF($B14="","",IFERROR(Accrual!G$221,"")) | F14: =IF($B14="","",IFERROR($E14/$C$5,"")) | G14: =IF($B14="","",SUM($E$13:$E14)) | H14: =IF($B14="","",IFERROR($G14/$C$5,"")) | I14: =IF($B14="","",IFERROR($H14*365/$D14,"")) | J14: =IF($B14="","",Expiries!$I17) | K14: =IF($B14="","",IFERROR(Accrual!G$309,"")) | L14: =IF($B14="","",IFERROR($K14/$C$6,"")) | M14: =IF($B14="","",SUM($K$13:$K14)) | N14: =IF($B14="","",IFERROR($M14/$C$6,"")) | O14: =IF($B14="","",IFERROR($N14*365/($J14-$C$7),"")) | P14: =IF($B14="","",IFERROR(($H14-$N14)*10000,"")) | Q14: =IF($B14="","",IFERROR(($I14-$O14)*10000,"")) | R14: =IF($B14="","",Expiries!$L17)
B15: =IF(Expiries!$B18="","",Expiries!$C18) | C15: =IF($B15="","",Expiries!$F18) | D15: =IF($B15="","",$C15-$C$7) | E15: =IF($B15="","",IFERROR(Accrual!H$221,"")) | F15: =IF($B15="","",IFERROR($E15/$C$5,"")) | G15: =IF($B15="","",SUM($E$13:$E15)) | H15: =IF($B15="","",IFERROR($G15/$C$5,"")) | I15: =IF($B15="","",IFERROR($H15*365/$D15,"")) | J15: =IF($B15="","",Expiries!$I18) | K15: =IF($B15="","",IFERROR(Accrual!H$309,"")) | L15: =IF($B15="","",IFERROR($K15/$C$6,"")) | M15: =IF($B15="","",SUM($K$13:$K15)) | N15: =IF($B15="","",IFERROR($M15/$C$6,"")) | O15: =IF($B15="","",IFERROR($N15*365/($J15-$C$7),"")) | P15: =IF($B15="","",IFERROR(($H15-$N15)*10000,"")) | Q15: =IF($B15="","",IFERROR(($I15-$O15)*10000,"")) | R15: =IF($B15="","",Expiries!$L18)
B16: =IF(Expiries!$B19="","",Expiries!$C19) | C16: =IF($B16="","",Expiries!$F19) | D16: =IF($B16="","",$C16-$C$7) | E16: =IF($B16="","",IFERROR(Accrual!I$221,"")) | F16: =IF($B16="","",IFERROR($E16/$C$5,"")) | G16: =IF($B16="","",SUM($E$13:$E16)) | H16: =IF($B16="","",IFERROR($G16/$C$5,"")) | I16: =IF($B16="","",IFERROR($H16*365/$D16,"")) | J16: =IF($B16="","",Expiries!$I19) | K16: =IF($B16="","",IFERROR(Accrual!I$309,"")) | L16: =IF($B16="","",IFERROR($K16/$C$6,"")) | M16: =IF($B16="","",SUM($K$13:$K16)) | N16: =IF($B16="","",IFERROR($M16/$C$6,"")) | O16: =IF($B16="","",IFERROR($N16*365/($J16-$C$7),"")) | P16: =IF($B16="","",IFERROR(($H16-$N16)*10000,"")) | Q16: =IF($B16="","",IFERROR(($I16-$O16)*10000,"")) | R16: =IF($B16="","",Expiries!$L19)
B17: =IF(Expiries!$B20="","",Expiries!$C20) | C17: =IF($B17="","",Expiries!$F20) | D17: =IF($B17="","",$C17-$C$7) | E17: =IF($B17="","",IFERROR(Accrual!J$221,"")) | F17: =IF($B17="","",IFERROR($E17/$C$5,"")) | G17: =IF($B17="","",SUM($E$13:$E17)) | H17: =IF($B17="","",IFERROR($G17/$C$5,"")) | I17: =IF($B17="","",IFERROR($H17*365/$D17,"")) | J17: =IF($B17="","",Expiries!$I20) | K17: =IF($B17="","",IFERROR(Accrual!J$309,"")) | L17: =IF($B17="","",IFERROR($K17/$C$6,"")) | M17: =IF($B17="","",SUM($K$13:$K17)) | N17: =IF($B17="","",IFERROR($M17/$C$6,"")) | O17: =IF($B17="","",IFERROR($N17*365/($J17-$C$7),"")) | P17: =IF($B17="","",IFERROR(($H17-$N17)*10000,"")) | Q17: =IF($B17="","",IFERROR(($I17-$O17)*10000,"")) | R17: =IF($B17="","",Expiries!$L20)
B18: =IF(Expiries!$B21="","",Expiries!$C21) | C18: =IF($B18="","",Expiries!$F21) | D18: =IF($B18="","",$C18-$C$7) | E18: =IF($B18="","",IFERROR(Accrual!K$221,"")) | F18: =IF($B18="","",IFERROR($E18/$C$5,"")) | G18: =IF($B18="","",SUM($E$13:$E18)) | H18: =IF($B18="","",IFERROR($G18/$C$5,"")) | I18: =IF($B18="","",IFERROR($H18*365/$D18,"")) | J18: =IF($B18="","",Expiries!$I21) | K18: =IF($B18="","",IFERROR(Accrual!K$309,"")) | L18: =IF($B18="","",IFERROR($K18/$C$6,"")) | M18: =IF($B18="","",SUM($K$13:$K18)) | N18: =IF($B18="","",IFERROR($M18/$C$6,"")) | O18: =IF($B18="","",IFERROR($N18*365/($J18-$C$7),"")) | P18: =IF($B18="","",IFERROR(($H18-$N18)*10000,"")) | Q18: =IF($B18="","",IFERROR(($I18-$O18)*10000,"")) | R18: =IF($B18="","",Expiries!$L21)
B19: =IF(Expiries!$B22="","",Expiries!$C22) | C19: =IF($B19="","",Expiries!$F22) | D19: =IF($B19="","",$C19-$C$7) | E19: =IF($B19="","",IFERROR(Accrual!L$221,"")) | F19: =IF($B19="","",IFERROR($E19/$C$5,"")) | G19: =IF($B19="","",SUM($E$13:$E19)) | H19: =IF($B19="","",IFERROR($G19/$C$5,"")) | I19: =IF($B19="","",IFERROR($H19*365/$D19,"")) | J19: =IF($B19="","",Expiries!$I22) | K19: =IF($B19="","",IFERROR(Accrual!L$309,"")) | L19: =IF($B19="","",IFERROR($K19/$C$6,"")) | M19: =IF($B19="","",SUM($K$13:$K19)) | N19: =IF($B19="","",IFERROR($M19/$C$6,"")) | O19: =IF($B19="","",IFERROR($N19*365/($J19-$C$7),"")) | P19: =IF($B19="","",IFERROR(($H19-$N19)*10000,"")) | Q19: =IF($B19="","",IFERROR(($I19-$O19)*10000,"")) | R19: =IF($B19="","",Expiries!$L22)
B20: =IF(Expiries!$B23="","",Expiries!$C23) | C20: =IF($B20="","",Expiries!$F23) | D20: =IF($B20="","",$C20-$C$7) | E20: =IF($B20="","",IFERROR(Accrual!M$221,"")) | F20: =IF($B20="","",IFERROR($E20/$C$5,"")) | G20: =IF($B20="","",SUM($E$13:$E20)) | H20: =IF($B20="","",IFERROR($G20/$C$5,"")) | I20: =IF($B20="","",IFERROR($H20*365/$D20,"")) | J20: =IF($B20="","",Expiries!$I23) | K20: =IF($B20="","",IFERROR(Accrual!M$309,"")) | L20: =IF($B20="","",IFERROR($K20/$C$6,"")) | M20: =IF($B20="","",SUM($K$13:$K20)) | N20: =IF($B20="","",IFERROR($M20/$C$6,"")) | O20: =IF($B20="","",IFERROR($N20*365/($J20-$C$7),"")) | P20: =IF($B20="","",IFERROR(($H20-$N20)*10000,"")) | Q20: =IF($B20="","",IFERROR(($I20-$O20)*10000,"")) | R20: =IF($B20="","",Expiries!$L23)
B21: =IF(Expiries!$B24="","",Expiries!$C24) | C21: =IF($B21="","",Expiries!$F24) | D21: =IF($B21="","",$C21-$C$7) | E21: =IF($B21="","",IFERROR(Accrual!N$221,"")) | F21: =IF($B21="","",IFERROR($E21/$C$5,"")) | G21: =IF($B21="","",SUM($E$13:$E21)) | H21: =IF($B21="","",IFERROR($G21/$C$5,"")) | I21: =IF($B21="","",IFERROR($H21*365/$D21,"")) | J21: =IF($B21="","",Expiries!$I24) | K21: =IF($B21="","",IFERROR(Accrual!N$309,"")) | L21: =IF($B21="","",IFERROR($K21/$C$6,"")) | M21: =IF($B21="","",SUM($K$13:$K21)) | N21: =IF($B21="","",IFERROR($M21/$C$6,"")) | O21: =IF($B21="","",IFERROR($N21*365/($J21-$C$7),"")) | P21: =IF($B21="","",IFERROR(($H21-$N21)*10000,"")) | Q21: =IF($B21="","",IFERROR(($I21-$O21)*10000,"")) | R21: =IF($B21="","",Expiries!$L24)
B22: =IF(Expiries!$B25="","",Expiries!$C25) | C22: =IF($B22="","",Expiries!$F25) | D22: =IF($B22="","",$C22-$C$7) | E22: =IF($B22="","",IFERROR(Accrual!O$221,"")) | F22: =IF($B22="","",IFERROR($E22/$C$5,"")) | G22: =IF($B22="","",SUM($E$13:$E22)) | H22: =IF($B22="","",IFERROR($G22/$C$5,"")) | I22: =IF($B22="","",IFERROR($H22*365/$D22,"")) | J22: =IF($B22="","",Expiries!$I25) | K22: =IF($B22="","",IFERROR(Accrual!O$309,"")) | L22: =IF($B22="","",IFERROR($K22/$C$6,"")) | M22: =IF($B22="","",SUM($K$13:$K22)) | N22: =IF($B22="","",IFERROR($M22/$C$6,"")) | O22: =IF($B22="","",IFERROR($N22*365/($J22-$C$7),"")) | P22: =IF($B22="","",IFERROR(($H22-$N22)*10000,"")) | Q22: =IF($B22="","",IFERROR(($I22-$O22)*10000,"")) | R22: =IF($B22="","",Expiries!$L25)
B23: =IF(Expiries!$B26="","",Expiries!$C26) | C23: =IF($B23="","",Expiries!$F26) | D23: =IF($B23="","",$C23-$C$7) | E23: =IF($B23="","",IFERROR(Accrual!P$221,"")) | F23: =IF($B23="","",IFERROR($E23/$C$5,"")) | G23: =IF($B23="","",SUM($E$13:$E23)) | H23: =IF($B23="","",IFERROR($G23/$C$5,"")) | I23: =IF($B23="","",IFERROR($H23*365/$D23,"")) | J23: =IF($B23="","",Expiries!$I26) | K23: =IF($B23="","",IFERROR(Accrual!P$309,"")) | L23: =IF($B23="","",IFERROR($K23/$C$6,"")) | M23: =IF($B23="","",SUM($K$13:$K23)) | N23: =IF($B23="","",IFERROR($M23/$C$6,"")) | O23: =IF($B23="","",IFERROR($N23*365/($J23-$C$7),"")) | P23: =IF($B23="","",IFERROR(($H23-$N23)*10000,"")) | Q23: =IF($B23="","",IFERROR(($I23-$O23)*10000,"")) | R23: =IF($B23="","",Expiries!$L26)
B24: =IF(Expiries!$B27="","",Expiries!$C27) | C24: =IF($B24="","",Expiries!$F27) | D24: =IF($B24="","",$C24-$C$7) | E24: =IF($B24="","",IFERROR(Accrual!Q$221,"")) | F24: =IF($B24="","",IFERROR($E24/$C$5,"")) | G24: =IF($B24="","",SUM($E$13:$E24)) | H24: =IF($B24="","",IFERROR($G24/$C$5,"")) | I24: =IF($B24="","",IFERROR($H24*365/$D24,"")) | J24: =IF($B24="","",Expiries!$I27) | K24: =IF($B24="","",IFERROR(Accrual!Q$309,"")) | L24: =IF($B24="","",IFERROR($K24/$C$6,"")) | M24: =IF($B24="","",SUM($K$13:$K24)) | N24: =IF($B24="","",IFERROR($M24/$C$6,"")) | O24: =IF($B24="","",IFERROR($N24*365/($J24-$C$7),"")) | P24: =IF($B24="","",IFERROR(($H24-$N24)*10000,"")) | Q24: =IF($B24="","",IFERROR(($I24-$O24)*10000,"")) | R24: =IF($B24="","",Expiries!$L27)
B25: =IF(Expiries!$B28="","",Expiries!$C28) | C25: =IF($B25="","",Expiries!$F28) | D25: =IF($B25="","",$C25-$C$7) | E25: =IF($B25="","",IFERROR(Accrual!R$221,"")) | F25: =IF($B25="","",IFERROR($E25/$C$5,"")) | G25: =IF($B25="","",SUM($E$13:$E25)) | H25: =IF($B25="","",IFERROR($G25/$C$5,"")) | I25: =IF($B25="","",IFERROR($H25*365/$D25,"")) | J25: =IF($B25="","",Expiries!$I28) | K25: =IF($B25="","",IFERROR(Accrual!R$309,"")) | L25: =IF($B25="","",IFERROR($K25/$C$6,"")) | M25: =IF($B25="","",SUM($K$13:$K25)) | N25: =IF($B25="","",IFERROR($M25/$C$6,"")) | O25: =IF($B25="","",IFERROR($N25*365/($J25-$C$7),"")) | P25: =IF($B25="","",IFERROR(($H25-$N25)*10000,"")) | Q25: =IF($B25="","",IFERROR(($I25-$O25)*10000,"")) | R25: =IF($B25="","",Expiries!$L28)
B26: =IF(Expiries!$B29="","",Expiries!$C29) | C26: =IF($B26="","",Expiries!$F29) | D26: =IF($B26="","",$C26-$C$7) | E26: =IF($B26="","",IFERROR(Accrual!S$221,"")) | F26: =IF($B26="","",IFERROR($E26/$C$5,"")) | G26: =IF($B26="","",SUM($E$13:$E26)) | H26: =IF($B26="","",IFERROR($G26/$C$5,"")) | I26: =IF($B26="","",IFERROR($H26*365/$D26,"")) | J26: =IF($B26="","",Expiries!$I29) | K26: =IF($B26="","",IFERROR(Accrual!S$309,"")) | L26: =IF($B26="","",IFERROR($K26/$C$6,"")) | M26: =IF($B26="","",SUM($K$13:$K26)) | N26: =IF($B26="","",IFERROR($M26/$C$6,"")) | O26: =IF($B26="","",IFERROR($N26*365/($J26-$C$7),"")) | P26: =IF($B26="","",IFERROR(($H26-$N26)*10000,"")) | Q26: =IF($B26="","",IFERROR(($I26-$O26)*10000,"")) | R26: =IF($B26="","",Expiries!$L29)
B27: =IF(Expiries!$B30="","",Expiries!$C30) | C27: =IF($B27="","",Expiries!$F30) | D27: =IF($B27="","",$C27-$C$7) | E27: =IF($B27="","",IFERROR(Accrual!T$221,"")) | F27: =IF($B27="","",IFERROR($E27/$C$5,"")) | G27: =IF($B27="","",SUM($E$13:$E27)) | H27: =IF($B27="","",IFERROR($G27/$C$5,"")) | I27: =IF($B27="","",IFERROR($H27*365/$D27,"")) | J27: =IF($B27="","",Expiries!$I30) | K27: =IF($B27="","",IFERROR(Accrual!T$309,"")) | L27: =IF($B27="","",IFERROR($K27/$C$6,"")) | M27: =IF($B27="","",SUM($K$13:$K27)) | N27: =IF($B27="","",IFERROR($M27/$C$6,"")) | O27: =IF($B27="","",IFERROR($N27*365/($J27-$C$7),"")) | P27: =IF($B27="","",IFERROR(($H27-$N27)*10000,"")) | Q27: =IF($B27="","",IFERROR(($I27-$O27)*10000,"")) | R27: =IF($B27="","",Expiries!$L30)
B28: =IF(Expiries!$B31="","",Expiries!$C31) | C28: =IF($B28="","",Expiries!$F31) | D28: =IF($B28="","",$C28-$C$7) | E28: =IF($B28="","",IFERROR(Accrual!U$221,"")) | F28: =IF($B28="","",IFERROR($E28/$C$5,"")) | G28: =IF($B28="","",SUM($E$13:$E28)) | H28: =IF($B28="","",IFERROR($G28/$C$5,"")) | I28: =IF($B28="","",IFERROR($H28*365/$D28,"")) | J28: =IF($B28="","",Expiries!$I31) | K28: =IF($B28="","",IFERROR(Accrual!U$309,"")) | L28: =IF($B28="","",IFERROR($K28/$C$6,"")) | M28: =IF($B28="","",SUM($K$13:$K28)) | N28: =IF($B28="","",IFERROR($M28/$C$6,"")) | O28: =IF($B28="","",IFERROR($N28*365/($J28-$C$7),"")) | P28: =IF($B28="","",IFERROR(($H28-$N28)*10000,"")) | Q28: =IF($B28="","",IFERROR(($I28-$O28)*10000,"")) | R28: =IF($B28="","",Expiries!$L31)
B32: FRANKING VIEW - CREDIT VALUE BY CONTRACT
B33: Franked share uses each stock's company-level franked % (blank = 100%). Credit = franked dividend x t/(1-t) with t = 'Index Summary'!C6. Grossed-up = cash + credit.
C34: S&P/ASX 200 (AS51) | H34: MSCI AUSTRALIA (MXAU) | M34: SPREAD | T34: o/w SPECIALS + CAPITAL RETURNS (divisor-adjusted: the index does not drop; futures FV excludes them unless toggled on)
B35: Contract | C35: Franked (% of dvd) | D35: Credit (pts) | E35: Cum credit (pts) | F35: Grossed cum yld (%) | G35: Ann grossed yld (%) | H35: Franked (% of dvd) | I35: Credit (pts) | J35: Cum credit (pts) | K35: Grossed cum yld (%) | L35: Ann grossed yld (%) | M35: Grossed sprd (bps) | N35: Ann grossed sprd (bps) | T35: A: period sp (pts) | U35: A: cum sp (pts) | V35: A: period sp credits (pts) | W35: A: cum sp credits (pts) | X35: M: period sp (pts) | Y35: M: cum sp (pts) | Z35: M: period sp credits (pts) | AA35: M: cum sp credits (pts)
B36: =IF(Expiries!$B16="","",Expiries!$C16) | C36: =IF($B36="","",IFERROR(Accrual!W$221/Accrual!F$221,"")) | D36: =IF($B36="","",IFERROR(Accrual!W$221*'Index Summary'!$C$6/(1-'Index Summary'!$C$6),"")) | E36: =IF($B36="","",SUM($D$36:$D36)) | F36: =IF($B36="","",IFERROR(($G13+$E36)/$C$5,"")) | G36: =IF($B36="","",IFERROR($F36*365/$D13,"")) | H36: =IF($B36="","",IFERROR(Accrual!W$309/Accrual!F$309,"")) | I36: =IF($B36="","",IFERROR(Accrual!W$309*'Index Summary'!$C$6/(1-'Index Summary'!$C$6),"")) | J36: =IF($B36="","",SUM($I$36:$I36)) | K36: =IF($B36="","",IFERROR(($M13+$J36)/$C$6,"")) | L36: =IF($B36="","",IFERROR($K36*365/($J13-$C$7),"")) | M36: =IF($B36="","",IFERROR(($F36-$K36)*10000,"")) | N36: =IF($B36="","",IFERROR(($G36-$L36)*10000,"")) | T36: =IF($B36="","",IFERROR(Accrual!AQ$221,"")) | U36: =IF($B36="","",SUM($T$36:$T36)) | V36: =IF($B36="","",IFERROR(Accrual!BH$221*'Index Summary'!$C$6/(1-'Index Summary'!$C$6),"")) | W36: =IF($B36="","",SUM($V$36:$V36)) | X36: =IF($B36="","",IFERROR(Accrual!AQ$309,"")) | Y36: =IF($B36="","",SUM($X$36:$X36)) | Z36: =IF($B36="","",IFERROR(Accrual!BH$309*'Index Summary'!$C$6/(1-'Index Summary'!$C$6),"")) | AA36: =IF($B36="","",SUM($Z$36:$Z36))
B37: =IF(Expiries!$B17="","",Expiries!$C17) | C37: =IF($B37="","",IFERROR(Accrual!X$221/Accrual!G$221,"")) | D37: =IF($B37="","",IFERROR(Accrual!X$221*'Index Summary'!$C$6/(1-'Index Summary'!$C$6),"")) | E37: =IF($B37="","",SUM($D$36:$D37)) | F37: =IF($B37="","",IFERROR(($G14+$E37)/$C$5,"")) | G37: =IF($B37="","",IFERROR($F37*365/$D14,"")) | H37: =IF($B37="","",IFERROR(Accrual!X$309/Accrual!G$309,"")) | I37: =IF($B37="","",IFERROR(Accrual!X$309*'Index Summary'!$C$6/(1-'Index Summary'!$C$6),"")) | J37: =IF($B37="","",SUM($I$36:$I37)) | K37: =IF($B37="","",IFERROR(($M14+$J37)/$C$6,"")) | L37: =IF($B37="","",IFERROR($K37*365/($J14-$C$7),"")) | M37: =IF($B37="","",IFERROR(($F37-$K37)*10000,"")) | N37: =IF($B37="","",IFERROR(($G37-$L37)*10000,"")) | T37: =IF($B37="","",IFERROR(Accrual!AR$221,"")) | U37: =IF($B37="","",SUM($T$36:$T37)) | V37: =IF($B37="","",IFERROR(Accrual!BI$221*'Index Summary'!$C$6/(1-'Index Summary'!$C$6),"")) | W37: =IF($B37="","",SUM($V$36:$V37)) | X37: =IF($B37="","",IFERROR(Accrual!AR$309,"")) | Y37: =IF($B37="","",SUM($X$36:$X37)) | Z37: =IF($B37="","",IFERROR(Accrual!BI$309*'Index Summary'!$C$6/(1-'Index Summary'!$C$6),"")) | AA37: =IF($B37="","",SUM($Z$36:$Z37))
B38: =IF(Expiries!$B18="","",Expiries!$C18) | C38: =IF($B38="","",IFERROR(Accrual!Y$221/Accrual!H$221,"")) | D38: =IF($B38="","",IFERROR(Accrual!Y$221*'Index Summary'!$C$6/(1-'Index Summary'!$C$6),"")) | E38: =IF($B38="","",SUM($D$36:$D38)) | F38: =IF($B38="","",IFERROR(($G15+$E38)/$C$5,"")) | G38: =IF($B38="","",IFERROR($F38*365/$D15,"")) | H38: =IF($B38="","",IFERROR(Accrual!Y$309/Accrual!H$309,"")) | I38: =IF($B38="","",IFERROR(Accrual!Y$309*'Index Summary'!$C$6/(1-'Index Summary'!$C$6),"")) | J38: =IF($B38="","",SUM($I$36:$I38)) | K38: =IF($B38="","",IFERROR(($M15+$J38)/$C$6,"")) | L38: =IF($B38="","",IFERROR($K38*365/($J15-$C$7),"")) | M38: =IF($B38="","",IFERROR(($F38-$K38)*10000,"")) | N38: =IF($B38="","",IFERROR(($G38-$L38)*10000,"")) | T38: =IF($B38="","",IFERROR(Accrual!AS$221,"")) | U38: =IF($B38="","",SUM($T$36:$T38)) | V38: =IF($B38="","",IFERROR(Accrual!BJ$221*'Index Summary'!$C$6/(1-'Index Summary'!$C$6),"")) | W38: =IF($B38="","",SUM($V$36:$V38)) | X38: =IF($B38="","",IFERROR(Accrual!AS$309,"")) | Y38: =IF($B38="","",SUM($X$36:$X38)) | Z38: =IF($B38="","",IFERROR(Accrual!BJ$309*'Index Summary'!$C$6/(1-'Index Summary'!$C$6),"")) | AA38: =IF($B38="","",SUM($Z$36:$Z38))
B39: =IF(Expiries!$B19="","",Expiries!$C19) | C39: =IF($B39="","",IFERROR(Accrual!Z$221/Accrual!I$221,"")) | D39: =IF($B39="","",IFERROR(Accrual!Z$221*'Index Summary'!$C$6/(1-'Index Summary'!$C$6),"")) | E39: =IF($B39="","",SUM($D$36:$D39)) | F39: =IF($B39="","",IFERROR(($G16+$E39)/$C$5,"")) | G39: =IF($B39="","",IFERROR($F39*365/$D16,"")) | H39: =IF($B39="","",IFERROR(Accrual!Z$309/Accrual!I$309,"")) | I39: =IF($B39="","",IFERROR(Accrual!Z$309*'Index Summary'!$C$6/(1-'Index Summary'!$C$6),"")) | J39: =IF($B39="","",SUM($I$36:$I39)) | K39: =IF($B39="","",IFERROR(($M16+$J39)/$C$6,"")) | L39: =IF($B39="","",IFERROR($K39*365/($J16-$C$7),"")) | M39: =IF($B39="","",IFERROR(($F39-$K39)*10000,"")) | N39: =IF($B39="","",IFERROR(($G39-$L39)*10000,"")) | T39: =IF($B39="","",IFERROR(Accrual!AT$221,"")) | U39: =IF($B39="","",SUM($T$36:$T39)) | V39: =IF($B39="","",IFERROR(Accrual!BK$221*'Index Summary'!$C$6/(1-'Index Summary'!$C$6),"")) | W39: =IF($B39="","",SUM($V$36:$V39)) | X39: =IF($B39="","",IFERROR(Accrual!AT$309,"")) | Y39: =IF($B39="","",SUM($X$36:$X39)) | Z39: =IF($B39="","",IFERROR(Accrual!BK$309*'Index Summary'!$C$6/(1-'Index Summary'!$C$6),"")) | AA39: =IF($B39="","",SUM($Z$36:$Z39))
B40: =IF(Expiries!$B20="","",Expiries!$C20) | C40: =IF($B40="","",IFERROR(Accrual!AA$221/Accrual!J$221,"")) | D40: =IF($B40="","",IFERROR(Accrual!AA$221*'Index Summary'!$C$6/(1-'Index Summary'!$C$6),"")) | E40: =IF($B40="","",SUM($D$36:$D40)) | F40: =IF($B40="","",IFERROR(($G17+$E40)/$C$5,"")) | G40: =IF($B40="","",IFERROR($F40*365/$D17,"")) | H40: =IF($B40="","",IFERROR(Accrual!AA$309/Accrual!J$309,"")) | I40: =IF($B40="","",IFERROR(Accrual!AA$309*'Index Summary'!$C$6/(1-'Index Summary'!$C$6),"")) | J40: =IF($B40="","",SUM($I$36:$I40)) | K40: =IF($B40="","",IFERROR(($M17+$J40)/$C$6,"")) | L40: =IF($B40="","",IFERROR($K40*365/($J17-$C$7),"")) | M40: =IF($B40="","",IFERROR(($F40-$K40)*10000,"")) | N40: =IF($B40="","",IFERROR(($G40-$L40)*10000,"")) | T40: =IF($B40="","",IFERROR(Accrual!AU$221,"")) | U40: =IF($B40="","",SUM($T$36:$T40)) | V40: =IF($B40="","",IFERROR(Accrual!BL$221*'Index Summary'!$C$6/(1-'Index Summary'!$C$6),"")) | W40: =IF($B40="","",SUM($V$36:$V40)) | X40: =IF($B40="","",IFERROR(Accrual!AU$309,"")) | Y40: =IF($B40="","",SUM($X$36:$X40)) | Z40: =IF($B40="","",IFERROR(Accrual!BL$309*'Index Summary'!$C$6/(1-'Index Summary'!$C$6),"")) | AA40: =IF($B40="","",SUM($Z$36:$Z40))
B41: =IF(Expiries!$B21="","",Expiries!$C21) | C41: =IF($B41="","",IFERROR(Accrual!AB$221/Accrual!K$221,"")) | D41: =IF($B41="","",IFERROR(Accrual!AB$221*'Index Summary'!$C$6/(1-'Index Summary'!$C$6),"")) | E41: =IF($B41="","",SUM($D$36:$D41)) | F41: =IF($B41="","",IFERROR(($G18+$E41)/$C$5,"")) | G41: =IF($B41="","",IFERROR($F41*365/$D18,"")) | H41: =IF($B41="","",IFERROR(Accrual!AB$309/Accrual!K$309,"")) | I41: =IF($B41="","",IFERROR(Accrual!AB$309*'Index Summary'!$C$6/(1-'Index Summary'!$C$6),"")) | J41: =IF($B41="","",SUM($I$36:$I41)) | K41: =IF($B41="","",IFERROR(($M18+$J41)/$C$6,"")) | L41: =IF($B41="","",IFERROR($K41*365/($J18-$C$7),"")) | M41: =IF($B41="","",IFERROR(($F41-$K41)*10000,"")) | N41: =IF($B41="","",IFERROR(($G41-$L41)*10000,"")) | T41: =IF($B41="","",IFERROR(Accrual!AV$221,"")) | U41: =IF($B41="","",SUM($T$36:$T41)) | V41: =IF($B41="","",IFERROR(Accrual!BM$221*'Index Summary'!$C$6/(1-'Index Summary'!$C$6),"")) | W41: =IF($B41="","",SUM($V$36:$V41)) | X41: =IF($B41="","",IFERROR(Accrual!AV$309,"")) | Y41: =IF($B41="","",SUM($X$36:$X41)) | Z41: =IF($B41="","",IFERROR(Accrual!BM$309*'Index Summary'!$C$6/(1-'Index Summary'!$C$6),"")) | AA41: =IF($B41="","",SUM($Z$36:$Z41))
B42: =IF(Expiries!$B22="","",Expiries!$C22) | C42: =IF($B42="","",IFERROR(Accrual!AC$221/Accrual!L$221,"")) | D42: =IF($B42="","",IFERROR(Accrual!AC$221*'Index Summary'!$C$6/(1-'Index Summary'!$C$6),"")) | E42: =IF($B42="","",SUM($D$36:$D42)) | F42: =IF($B42="","",IFERROR(($G19+$E42)/$C$5,"")) | G42: =IF($B42="","",IFERROR($F42*365/$D19,"")) | H42: =IF($B42="","",IFERROR(Accrual!AC$309/Accrual!L$309,"")) | I42: =IF($B42="","",IFERROR(Accrual!AC$309*'Index Summary'!$C$6/(1-'Index Summary'!$C$6),"")) | J42: =IF($B42="","",SUM($I$36:$I42)) | K42: =IF($B42="","",IFERROR(($M19+$J42)/$C$6,"")) | L42: =IF($B42="","",IFERROR($K42*365/($J19-$C$7),"")) | M42: =IF($B42="","",IFERROR(($F42-$K42)*10000,"")) | N42: =IF($B42="","",IFERROR(($G42-$L42)*10000,"")) | T42: =IF($B42="","",IFERROR(Accrual!AW$221,"")) | U42: =IF($B42="","",SUM($T$36:$T42)) | V42: =IF($B42="","",IFERROR(Accrual!BN$221*'Index Summary'!$C$6/(1-'Index Summary'!$C$6),"")) | W42: =IF($B42="","",SUM($V$36:$V42)) | X42: =IF($B42="","",IFERROR(Accrual!AW$309,"")) | Y42: =IF($B42="","",SUM($X$36:$X42)) | Z42: =IF($B42="","",IFERROR(Accrual!BN$309*'Index Summary'!$C$6/(1-'Index Summary'!$C$6),"")) | AA42: =IF($B42="","",SUM($Z$36:$Z42))
B43: =IF(Expiries!$B23="","",Expiries!$C23) | C43: =IF($B43="","",IFERROR(Accrual!AD$221/Accrual!M$221,"")) | D43: =IF($B43="","",IFERROR(Accrual!AD$221*'Index Summary'!$C$6/(1-'Index Summary'!$C$6),"")) | E43: =IF($B43="","",SUM($D$36:$D43)) | F43: =IF($B43="","",IFERROR(($G20+$E43)/$C$5,"")) | G43: =IF($B43="","",IFERROR($F43*365/$D20,"")) | H43: =IF($B43="","",IFERROR(Accrual!AD$309/Accrual!M$309,"")) | I43: =IF($B43="","",IFERROR(Accrual!AD$309*'Index Summary'!$C$6/(1-'Index Summary'!$C$6),"")) | J43: =IF($B43="","",SUM($I$36:$I43)) | K43: =IF($B43="","",IFERROR(($M20+$J43)/$C$6,"")) | L43: =IF($B43="","",IFERROR($K43*365/($J20-$C$7),"")) | M43: =IF($B43="","",IFERROR(($F43-$K43)*10000,"")) | N43: =IF($B43="","",IFERROR(($G43-$L43)*10000,"")) | T43: =IF($B43="","",IFERROR(Accrual!AX$221,"")) | U43: =IF($B43="","",SUM($T$36:$T43)) | V43: =IF($B43="","",IFERROR(Accrual!BO$221*'Index Summary'!$C$6/(1-'Index Summary'!$C$6),"")) | W43: =IF($B43="","",SUM($V$36:$V43)) | X43: =IF($B43="","",IFERROR(Accrual!AX$309,"")) | Y43: =IF($B43="","",SUM($X$36:$X43)) | Z43: =IF($B43="","",IFERROR(Accrual!BO$309*'Index Summary'!$C$6/(1-'Index Summary'!$C$6),"")) | AA43: =IF($B43="","",SUM($Z$36:$Z43))
B44: =IF(Expiries!$B24="","",Expiries!$C24) | C44: =IF($B44="","",IFERROR(Accrual!AE$221/Accrual!N$221,"")) | D44: =IF($B44="","",IFERROR(Accrual!AE$221*'Index Summary'!$C$6/(1-'Index Summary'!$C$6),"")) | E44: =IF($B44="","",SUM($D$36:$D44)) | F44: =IF($B44="","",IFERROR(($G21+$E44)/$C$5,"")) | G44: =IF($B44="","",IFERROR($F44*365/$D21,"")) | H44: =IF($B44="","",IFERROR(Accrual!AE$309/Accrual!N$309,"")) | I44: =IF($B44="","",IFERROR(Accrual!AE$309*'Index Summary'!$C$6/(1-'Index Summary'!$C$6),"")) | J44: =IF($B44="","",SUM($I$36:$I44)) | K44: =IF($B44="","",IFERROR(($M21+$J44)/$C$6,"")) | L44: =IF($B44="","",IFERROR($K44*365/($J21-$C$7),"")) | M44: =IF($B44="","",IFERROR(($F44-$K44)*10000,"")) | N44: =IF($B44="","",IFERROR(($G44-$L44)*10000,"")) | T44: =IF($B44="","",IFERROR(Accrual!AY$221,"")) | U44: =IF($B44="","",SUM($T$36:$T44)) | V44: =IF($B44="","",IFERROR(Accrual!BP$221*'Index Summary'!$C$6/(1-'Index Summary'!$C$6),"")) | W44: =IF($B44="","",SUM($V$36:$V44)) | X44: =IF($B44="","",IFERROR(Accrual!AY$309,"")) | Y44: =IF($B44="","",SUM($X$36:$X44)) | Z44: =IF($B44="","",IFERROR(Accrual!BP$309*'Index Summary'!$C$6/(1-'Index Summary'!$C$6),"")) | AA44: =IF($B44="","",SUM($Z$36:$Z44))
B45: =IF(Expiries!$B25="","",Expiries!$C25) | C45: =IF($B45="","",IFERROR(Accrual!AF$221/Accrual!O$221,"")) | D45: =IF($B45="","",IFERROR(Accrual!AF$221*'Index Summary'!$C$6/(1-'Index Summary'!$C$6),"")) | E45: =IF($B45="","",SUM($D$36:$D45)) | F45: =IF($B45="","",IFERROR(($G22+$E45)/$C$5,"")) | G45: =IF($B45="","",IFERROR($F45*365/$D22,"")) | H45: =IF($B45="","",IFERROR(Accrual!AF$309/Accrual!O$309,"")) | I45: =IF($B45="","",IFERROR(Accrual!AF$309*'Index Summary'!$C$6/(1-'Index Summary'!$C$6),"")) | J45: =IF($B45="","",SUM($I$36:$I45)) | K45: =IF($B45="","",IFERROR(($M22+$J45)/$C$6,"")) | L45: =IF($B45="","",IFERROR($K45*365/($J22-$C$7),"")) | M45: =IF($B45="","",IFERROR(($F45-$K45)*10000,"")) | N45: =IF($B45="","",IFERROR(($G45-$L45)*10000,"")) | T45: =IF($B45="","",IFERROR(Accrual!AZ$221,"")) | U45: =IF($B45="","",SUM($T$36:$T45)) | V45: =IF($B45="","",IFERROR(Accrual!BQ$221*'Index Summary'!$C$6/(1-'Index Summary'!$C$6),"")) | W45: =IF($B45="","",SUM($V$36:$V45)) | X45: =IF($B45="","",IFERROR(Accrual!AZ$309,"")) | Y45: =IF($B45="","",SUM($X$36:$X45)) | Z45: =IF($B45="","",IFERROR(Accrual!BQ$309*'Index Summary'!$C$6/(1-'Index Summary'!$C$6),"")) | AA45: =IF($B45="","",SUM($Z$36:$Z45))
B46: =IF(Expiries!$B26="","",Expiries!$C26) | C46: =IF($B46="","",IFERROR(Accrual!AG$221/Accrual!P$221,"")) | D46: =IF($B46="","",IFERROR(Accrual!AG$221*'Index Summary'!$C$6/(1-'Index Summary'!$C$6),"")) | E46: =IF($B46="","",SUM($D$36:$D46)) | F46: =IF($B46="","",IFERROR(($G23+$E46)/$C$5,"")) | G46: =IF($B46="","",IFERROR($F46*365/$D23,"")) | H46: =IF($B46="","",IFERROR(Accrual!AG$309/Accrual!P$309,"")) | I46: =IF($B46="","",IFERROR(Accrual!AG$309*'Index Summary'!$C$6/(1-'Index Summary'!$C$6),"")) | J46: =IF($B46="","",SUM($I$36:$I46)) | K46: =IF($B46="","",IFERROR(($M23+$J46)/$C$6,"")) | L46: =IF($B46="","",IFERROR($K46*365/($J23-$C$7),"")) | M46: =IF($B46="","",IFERROR(($F46-$K46)*10000,"")) | N46: =IF($B46="","",IFERROR(($G46-$L46)*10000,"")) | T46: =IF($B46="","",IFERROR(Accrual!BA$221,"")) | U46: =IF($B46="","",SUM($T$36:$T46)) | V46: =IF($B46="","",IFERROR(Accrual!BR$221*'Index Summary'!$C$6/(1-'Index Summary'!$C$6),"")) | W46: =IF($B46="","",SUM($V$36:$V46)) | X46: =IF($B46="","",IFERROR(Accrual!BA$309,"")) | Y46: =IF($B46="","",SUM($X$36:$X46)) | Z46: =IF($B46="","",IFERROR(Accrual!BR$309*'Index Summary'!$C$6/(1-'Index Summary'!$C$6),"")) | AA46: =IF($B46="","",SUM($Z$36:$Z46))
...

Sheet Futures FV
B2: FUTURES FAIR VALUE - AND THE FRANKING CREDIT PRICED IN
B3: Fair value = spot x (1 + rate x days/basis) - dividends to expiry. Type the traded futures price per contract: implied dividends = spot + carry - price, and the excess over your CASH dividend forecast, as a share of the franking credits available, is the franking the market is paying for.
B4: Overrides | C4: =IF(Override!$C$4="ON","ON - "&Override!$E$4&" row(s) live - the dividend columns below include YOUR numbers.","OFF - pure Bloomberg projections.")
AK5: AUD OIS CURVE (ICVS 159) | AP5: SPI FUTURES ROOT
B6: INPUTS | C6: AS51 (SPI, AUD) | D6: MXAU (USD) | AK6: curve tkr | AL6: YCSW0159 Index | AP6: root | AQ6: XP
B7: Spot - live (from Div by Expiry) | C7: ='Div by Expiry'!$C$5 | D7: ='Div by Expiry'!$C$6 | AK7: Tenor | AL7: Days | AM7: Ticker | AN7: % (live) | AO7: % zero
B8: Spot - override (optional) | G8: Type a spot here to match the moment you marked the futures - basis noise otherwise. | AK8: 1W | AL8: 7 | AM8: ADSO1Z Curncy | AN8: =IF($AM8="","",BDP($AM8,"PX_LAST")) | AO8: =IF($AN8="","",IF($AL8<=365,$AN8,IFERROR((1/((1-$AN8/100*(1/(1+INDEX($AN$8:$AN$17,MATCH(365,$AL$8:$AL$17,0))/100)))/(1+$AN8/100*($AL8-365)/365))-1)*365/$AL8*100,"")))
B9: SPOT USED | C9: =IF(ISNUMBER($C$8),$C$8,$C$7) | D9: =IF(ISNUMBER($D$8),$D$8,$D$7) | AK9: 1M | AL9: 30 | AM9: ADSOA Curncy | AN9: =IF($AM9="","",BDP($AM9,"PX_LAST")) | AO9: =IF($AN9="","",IF($AL9<=365,$AN9,IFERROR((1/((1-$AN9/100*(1/(1+INDEX($AN$8:$AN$17,MATCH(365,$AL$8:$AL$17,0))/100)))/(1+$AN9/100*($AL9-365)/365))-1)*365/$AL9*100,"")))
B10: Funding (% p.a.) - blank = AUD OIS curve | G10: BOTH legs price off the AUD OIS curve at the right, interpolated to each contract's own days (cols AI / AJ) - your MXAU basket is AUD-denominated. Type a number here to force one flat rate for that leg (this is how you replicate the exact rate a FAIR screen shows). Your bank's funding for a SPECIFIC expiry goes in the 'YOUR funding %' columns at the far right - a number there beats everything else for that contract only. | AK10: 2M | AL10: 61 | AM10: ADSOB Curncy | AN10: =IF($AM10="","",BDP($AM10,"PX_LAST")) | AO10: =IF($AN10="","",IF($AL10<=365,$AN10,IFERROR((1/((1-$AN10/100*(1/(1+INDEX($AN$8:$AN$17,MATCH(365,$AL$8:$AL$17,0))/100)))/(1+$AN10/100*($AL10-365)/365))-1)*365/$AL10*100,"")))
B11: Day-count basis | C11: 365 | D11: 365 | G11: AUD convention ACT/365 - both legs (the MXAU basket is AUD now). | AK11: 3M | AL11: 91 | AM11: ADSOC Curncy | AN11: =IF($AM11="","",BDP($AM11,"PX_LAST")) | AO11: =IF($AN11="","",IF($AL11<=365,$AN11,IFERROR((1/((1-$AN11/100*(1/(1+INDEX($AN$8:$AN$17,MATCH(365,$AL$8:$AL$17,0))/100)))/(1+$AN11/100*($AL11-365)/365))-1)*365/$AL11*100,"")))
B12: YOUR franking assumption (% of credits, 0-100) | C12: 0 | D12: 0 | G12: Drives the 'FV at your %' and 'mispricing' columns only. The offshore marginal investor in MXAU futures cannot use franking - 0 is the natural starting point there. | AK12: 4M | AL12: 122 | AM12: ADSOD Curncy | AN12: =IF($AM12="","",BDP($AM12,"PX_LAST")) | AO12: =IF($AN12="","",IF($AL12<=365,$AN12,IFERROR((1/((1-$AN12/100*(1/(1+INDEX($AN$8:$AN$17,MATCH(365,$AL$8:$AL$17,0))/100)))/(1+$AN12/100*($AL12-365)/365))-1)*365/$AL12*100,"")))
B13: Carry dividends to expiry? (Y/N) | C13: N | D13: =$C$13 | G13: One toggle for both legs (the MXAU cell mirrors it). Y future-values each period's dividends from the middle of its window to expiry at the funding rate - a few points on the far contracts. N is the plain desk convention. | AK13: 5M | AL13: 152 | AM13: ADSOE Curncy | AN13: =IF($AM13="","",BDP($AM13,"PX_LAST")) | AO13: =IF($AN13="","",IF($AL13<=365,$AN13,IFERROR((1/((1-$AN13/100*(1/(1+INDEX($AN$8:$AN$17,MATCH(365,$AL$8:$AL$17,0))/100)))/(1+$AN13/100*($AL13-365)/365))-1)*365/$AL13*100,"")))
B14: Funding spread over OIS (bp) | C14: 0 | D14: 0 | G14: Added on top of the interpolated OIS zero (ignored when a flat rate is typed above). Your real repo / TRS funding goes here; screen fair values often run off a bank-bill style rate ~10-25bp above OIS. | AK14: 6M | AL14: 183 | AM14: ADSOF Curncy | AN14: =IF($AM14="","",BDP($AM14,"PX_LAST")) | AO14: =IF($AN14="","",IF($AL14<=365,$AN14,IFERROR((1/((1-$AN14/100*(1/(1+INDEX($AN$8:$AN$17,MATCH(365,$AL$8:$AL$17,0))/100)))/(1+$AN14/100*($AL14-365)/365))-1)*365/$AL14*100,"")))
B15: MARKET price per row = your manual price (col AQ, far right) if typed, else the LIVE pull on the auto-built SPI ticker (root XP + month code F G H J K M N Q U V X Z + year digit: Aug26 = XPQ6). Serial months list on ASX but the volume sits in Mar / Jun / Sep / Dec. | T15: MXAU: NO listed price-index future exists. Eurex FMAU (ZTOA Index, USD) tracks MSCI Australia NET TOTAL RETURN - dividends are reinvested in it, so it prices no dividends and cannot be compared to these fair values. Type OTC / dealer price-index forward quotes only. | AK15: 9M | AL15: 274 | AM15: ADSOI Curncy | AN15: =IF($AM15="","",BDP($AM15,"PX_LAST")) | AO15: =IF($AN15="","",IF($AL15<=365,$AN15,IFERROR((1/((1-$AN15/100*(1/(1+INDEX($AN$8:$AN$17,MATCH(365,$AL$8:$AL$17,0))/100)))/(1+$AN15/100*($AL15-365)/365))-1)*365/$AL15*100,"")))
B16: Count SPECIAL dividends in FV? (Y/N) | C16: N | D16: N | G16: S&P and MSCI adjust the index DIVISOR for special dividends and capital returns - the index does not drop, so futures never price them: N excludes them (Div by Expiry keeps them, with an 'o/w specials' block showing exactly how much). MSCI only adjusts specials >=5% of the share price - set the MXAU cell to Y if the specials in window are small. | AK16: 1Y | AL16: 365 | AM16: ADSO1 Curncy | AN16: =IF($AM16="","",BDP($AM16,"PX_LAST")) | AO16: =IF($AN16="","",IF($AL16<=365,$AN16,IFERROR((1/((1-$AN16/100*(1/(1+INDEX($AN$8:$AN$17,MATCH(365,$AL$8:$AL$17,0))/100)))/(1+$AN16/100*($AL16-365)/365))-1)*365/$AL16*100,"")))
E17: S&P/ASX 200 (AS51 / SPI) | T17: MSCI AUSTRALIA (MXAU) | AG17: A vs M | AK17: 18M | AL17: 548 | AM17: ADSO1F Curncy | AN17: =IF($AM17="","",BDP($AM17,"PX_LAST")) | AO17: =IF($AN17="","",IF($AL17<=365,$AN17,IFERROR((1/((1-$AN17/100*(1/(1+INDEX($AN$8:$AN$17,MATCH(365,$AL$8:$AL$17,0))/100)))/(1+$AN17/100*($AL17-365)/365))-1)*365/$AL17*100,""))) | AP17: SPI PRICE FEED
B18: Contract | C18: Expiry | D18: Days | E18: Carry (pts) | F18: Divs to expiry (pts) | G18: Credits to expiry (pts) | H18: FV - no franking | I18: FV - full franking | J18: FV at YOUR % | K18: MARKET price | L18: Implied divs (pts) | M18: Franking priced (pts) | N18: FRANKING PRICED (%) | O18: Rich(+) / Cheap(-) vs your % (pts) | P18: same (bps) | R18: Expiry | S18: Days | T18: Carry (pts) | U18: Divs to expiry (pts) | V18: Credits to expiry (pts) | W18: FV - no franking | X18: FV - full franking | Y18: FV at YOUR % | Z18: MARKET price | AA18: Implied divs (pts) | AB18: Franking priced (pts) | AC18: FRANKING PRICED (%) | AD18: Rich(+) / Cheap(-) vs your % (pts) | AE18: same (bps) | AG18: Franking % A - M (pp) | AI18: AUD OIS % (AS51 exp) | AJ18: AUD OIS % (MXAU exp) | AK18: Tickers/days editable (blue) - confirm each ticker against the curve pull below or ICVS 159; keep Days ascending. '% zero' = the rate the maths uses: equal to the quote up to 1Y (AUD OIS pays once at maturity, ACT/365), bootstrapped past 1Y (annual coupon). | AP18: SPI ticker (auto) | AQ18: manual px (wins) | AR18: live px (LAST_PRICE) | AS18: YOUR funding % (AS51 exp) | AT18: YOUR funding % (MXAU exp) | AV18: net edge cash&carry (pts) | AW18: net edge reverse (pts) | AX18: ACTION (after costs)
B19: =IF('Div by Expiry'!$B13="","",'Div by Expiry'!$B13) | C19: =IF($B19="","",'Div by Expiry'!$C13) | D19: =IF($B19="","",'Div by Expiry'!$D13) | E19: =IF($B19="","",IF($AI19="","",$C$9*$AI19/100*$D19/$C$11)) | F19: =IF($B19="","",IF($C$13="N",'Div by Expiry'!$G13-IF($C$16="Y",0,'Div by Expiry'!$U36),IF($AI19="","",SUMPRODUCT('Div by Expiry'!$E$13:$E13,1+$AI19/100*($C19-(Expiries!$J$16:$J16+Expiries!$F$16:$F16)/2)/$C$11)-IF($C$16="Y",0,SUMPRODUCT('Div by Expiry'!$T$36:$T36,1+$AI19/100*($C19-(Expiries!$J$16:$J16+Expiries!$F$16:$F16)/2)/$C$11))))) | G19: =IF($B19="","",IF($C$13="N",'Div by Expiry'!$E36-IF($C$16="Y",0,'Div by Expiry'!$W36),IF($AI19="","",SUMPRODUCT('Div by Expiry'!$D$36:$D36,1+$AI19/100*($C19-(Expiries!$J$16:$J16+Expiries!$F$16:$F16)/2)/$C$11)-IF($C$16="Y",0,SUMPRODUCT('Div by Expiry'!$V$36:$V36,1+$AI19/100*($C19-(Expiries!$J$16:$J16+Expiries!$F$16:$F16)/2)/$C$11))))) | H19: =IF($B19="","",IF($E19="","",$C$9+$E19-$F19)) | I19: =IF($B19="","",IF($H19="","",$H19-$G19)) | J19: =IF($B19="","",IF($H19="","",$H19-$C$12/100*$G19)) | K19: =IF($B19="","",IF(ISNUMBER($AQ19),$AQ19,IF(ISNUMBER($AR19),$AR19,""))) | L19: =IF($B19="","",IF(N($K19)=0,"",IF($E19="","",$C$9+$E19-$K19))) | M19: =IF($L19="","",$L19-$F19) | N19: =IF($L19="","",IF($G19=0,"",$M19/$G19)) | O19: =IF($L19="","",$K19-$J19) | P19: =IF($L19="","",$O19/$C$9*10000) | R19: =IF($B19="","",'Div by Expiry'!$J13) | S19: =IF($B19="","",$R19-'Div by Expiry'!$C$7) | T19: =IF($B19="","",IF($AJ19="","",$D$9*$AJ19/100*$S19/$D$11)) | U19: =IF($B19="","",IF($C$13="N",'Div by Expiry'!$M13-IF($D$16="Y",0,'Div by Expiry'!$Y36),IF($AJ19="","",SUMPRODUCT('Div by Expiry'!$K$13:$K13,1+$AJ19/100*($R19-(Expiries!$K$16:$K16+Expiries!$I$16:$I16)/2)/$D$11)-IF($D$16="Y",0,SUMPRODUCT('Div by Expiry'!$X$36:$X36,1+$AJ19/100*($R19-(Expiries!$K$16:$K16+Expiries!$I$16:$I16)/2)/$D$11))))) | V19: =IF($B19="","",IF($C$13="N",'Div by Expiry'!$J36-IF($D$16="Y",0,'Div by Expiry'!$AA36),IF($AJ19="","",SUMPRODUCT('Div by Expiry'!$I$36:$I36,1+$AJ19/100*($R19-(Expiries!$K$16:$K16+Expiries!$I$16:$I16)/2)/$D$11)-IF($D$16="Y",0,SUMPRODUCT('Div by Expiry'!$Z$36:$Z36,1+$AJ19/100*($R19-(Expiries!$K$16:$K16+Expiries!$I$16:$I16)/2)/$D$11))))) | W19: =IF($B19="","",IF($T19="","",$D$9+$T19-$U19)) | X19: =IF($B19="","",IF($W19="","",$W19-$V19)) | Y19: =IF($B19="","",IF($W19="","",$W19-$D$12/100*$V19)) | AA19: =IF($B19="","",IF(N($Z19)=0,"",IF($T19="","",$D$9+$T19-$Z19))) | AB19: =IF($AA19="","",$AA19-$U19) | AC19: =IF($AA19="","",IF($V19=0,"",$AB19/$V19)) | AD19: =IF($AA19="","",$Z19-$Y19) | AE19: =IF($AA19="","",$AD19/$D$9*10000) | AG19: =IF($N19="","",IF($AC19="","",($N19-$AC19)*100)) | AI19: =IF($B19="","",IF(ISNUMBER($AS19),$AS19,IF(ISNUMBER($C$10),$C$10,IFERROR(IF(COUNTIF($AL$8:$AL$17,"<="&$D19)=0,$AO$8,IF(COUNTIF($AL$8:$AL$17,"<="&$D19)>=COUNT($AL$8:$AL$17),INDEX($AO$8:$AO$17,COUNT($AL$8:$AL$17)),INDEX($AO$8:$AO$17,COUNTIF($AL$8:$AL$17,"<="&$D19))+(INDEX($AO$8:$AO$17,COUNTIF($AL$8:$AL$17,"<="&$D19)+1)-INDEX($AO$8:$AO$17,COUNTIF($AL$8:$AL$17,"<="&$D19)))*($D19-INDEX($AL$8:$AL$17,COUNTIF($AL$8:$AL$17,"<="&$D19)))/(INDEX($AL$8:$AL$17,COUNTIF($AL$8:$AL$17,"<="&$D19)+1)-INDEX($AL$8:$AL$17,COUNTIF($AL$8:$AL$17,"<="&$D19)))))+N($C$14)/100,"")))) | AJ19: =IF($B19="","",IF(ISNUMBER($AT19),$AT19,IF(ISNUMBER($D$10),$D$10,IFERROR(IF(COUNTIF($AL$8:$AL$17,"<="&$S19)=0,$AO$8,IF(COUNTIF($AL$8:$AL$17,"<="&$S19)>=COUNT($AL$8:$AL$17),INDEX($AO$8:$AO$17,COUNT($AL$8:$AL$17)),INDEX($AO$8:$AO$17,COUNTIF($AL$8:$AL$17,"<="&$S19))+(INDEX($AO$8:$AO$17,COUNTIF($AL$8:$AL$17,"<="&$S19)+1)-INDEX($AO$8:$AO$17,COUNTIF($AL$8:$AL$17,"<="&$S19)))*($S19-INDEX($AL$8:$AL$17,COUNTIF($AL$8:$AL$17,"<="&$S19)))/(INDEX($AL$8:$AL$17,COUNTIF($AL$8:$AL$17,"<="&$S19)+1)-INDEX($AL$8:$AL$17,COUNTIF($AL$8:$AL$17,"<="&$S19)))))+N($D$14)/100,"")))) | AP19: =IF($B19="","",$AQ$6&CHOOSE(MONTH($C19),"F","G","H","J","K","M","N","Q","U","V","X","Z")&RIGHT(YEAR($C19),1)&" Index") | AR19: =IF($AP19="","",BDP($AP19,"LAST_PRICE")) | AV19: =IF($L19="","",$O19-$C$49) | AW19: =IF($L19="","",$H19-$K19-$C$50-$C$45/10000*$C$9*$D19/365) | AX19: =IF($L19="","",IF($AV19>0,"SELL FUT / BUY CASH +"&TEXT($AV19,"0.0")&" pts net",IF($AW19>0,"BUY FUT / SHORT CASH +"&TEXT($AW19,"0.0")&" pts net","no edge after costs")))
B20: =IF('Div by Expiry'!$B14="","",'Div by Expiry'!$B14) | C20: =IF($B20="","",'Div by Expiry'!$C14) | D20: =IF($B20="","",'Div by Expiry'!$D14) | E20: =IF($B20="","",IF($AI20="","",$C$9*$AI20/100*$D20/$C$11)) | F20: =IF($B20="","",IF($C$13="N",'Div by Expiry'!$G14-IF($C$16="Y",0,'Div by Expiry'!$U37),IF($AI20="","",SUMPRODUCT('Div by Expiry'!$E$13:$E14,1+$AI20/100*($C20-(Expiries!$J$16:$J17+Expiries!$F$16:$F17)/2)/$C$11)-IF($C$16="Y",0,SUMPRODUCT('Div by Expiry'!$T$36:$T37,1+$AI20/100*($C20-(Expiries!$J$16:$J17+Expiries!$F$16:$F17)/2)/$C$11))))) | G20: =IF($B20="","",IF($C$13="N",'Div by Expiry'!$E37-IF($C$16="Y",0,'Div by Expiry'!$W37),IF($AI20="","",SUMPRODUCT('Div by Expiry'!$D$36:$D37,1+$AI20/100*($C20-(Expiries!$J$16:$J17+Expiries!$F$16:$F17)/2)/$C$11)-IF($C$16="Y",0,SUMPRODUCT('Div by Expiry'!$V$36:$V37,1+$AI20/100*($C20-(Expiries!$J$16:$J17+Expiries!$F$16:$F17)/2)/$C$11))))) | H20: =IF($B20="","",IF($E20="","",$C$9+$E20-$F20)) | I20: =IF($B20="","",IF($H20="","",$H20-$G20)) | J20: =IF($B20="","",IF($H20="","",$H20-$C$12/100*$G20)) | K20: =IF($B20="","",IF(ISNUMBER($AQ20),$AQ20,IF(ISNUMBER($AR20),$AR20,""))) | L20: =IF($B20="","",IF(N($K20)=0,"",IF($E20="","",$C$9+$E20-$K20))) | M20: =IF($L20="","",$L20-$F20) | N20: =IF($L20="","",IF($G20=0,"",$M20/$G20)) | O20: =IF($L20="","",$K20-$J20) | P20: =IF($L20="","",$O20/$C$9*10000) | R20: =IF($B20="","",'Div by Expiry'!$J14) | S20: =IF($B20="","",$R20-'Div by Expiry'!$C$7) | T20: =IF($B20="","",IF($AJ20="","",$D$9*$AJ20/100*$S20/$D$11)) | U20: =IF($B20="","",IF($C$13="N",'Div by Expiry'!$M14-IF($D$16="Y",0,'Div by Expiry'!$Y37),IF($AJ20="","",SUMPRODUCT('Div by Expiry'!$K$13:$K14,1+$AJ20/100*($R20-(Expiries!$K$16:$K17+Expiries!$I$16:$I17)/2)/$D$11)-IF($D$16="Y",0,SUMPRODUCT('Div by Expiry'!$X$36:$X37,1+$AJ20/100*($R20-(Expiries!$K$16:$K17+Expiries!$I$16:$I17)/2)/$D$11))))) | V20: =IF($B20="","",IF($C$13="N",'Div by Expiry'!$J37-IF($D$16="Y",0,'Div by Expiry'!$AA37),IF($AJ20="","",SUMPRODUCT('Div by Expiry'!$I$36:$I37,1+$AJ20/100*($R20-(Expiries!$K$16:$K17+Expiries!$I$16:$I17)/2)/$D$11)-IF($D$16="Y",0,SUMPRODUCT('Div by Expiry'!$Z$36:$Z37,1+$AJ20/100*($R20-(Expiries!$K$16:$K17+Expiries!$I$16:$I17)/2)/$D$11))))) | W20: =IF($B20="","",IF($T20="","",$D$9+$T20-$U20)) | X20: =IF($B20="","",IF($W20="","",$W20-$V20)) | Y20: =IF($B20="","",IF($W20="","",$W20-$D$12/100*$V20)) | AA20: =IF($B20="","",IF(N($Z20)=0,"",IF($T20="","",$D$9+$T20-$Z20))) | AB20: =IF($AA20="","",$AA20-$U20) | AC20: =IF($AA20="","",IF($V20=0,"",$AB20/$V20)) | AD20: =IF($AA20="","",$Z20-$Y20) | AE20: =IF($AA20="","",$AD20/$D$9*10000) | AG20: =IF($N20="","",IF($AC20="","",($N20-$AC20)*100)) | AI20: =IF($B20="","",IF(ISNUMBER($AS20),$AS20,IF(ISNUMBER($C$10),$C$10,IFERROR(IF(COUNTIF($AL$8:$AL$17,"<="&$D20)=0,$AO$8,IF(COUNTIF($AL$8:$AL$17,"<="&$D20)>=COUNT($AL$8:$AL$17),INDEX($AO$8:$AO$17,COUNT($AL$8:$AL$17)),INDEX($AO$8:$AO$17,COUNTIF($AL$8:$AL$17,"<="&$D20))+(INDEX($AO$8:$AO$17,COUNTIF($AL$8:$AL$17,"<="&$D20)+1)-INDEX($AO$8:$AO$17,COUNTIF($AL$8:$AL$17,"<="&$D20)))*($D20-INDEX($AL$8:$AL$17,COUNTIF($AL$8:$AL$17,"<="&$D20)))/(INDEX($AL$8:$AL$17,COUNTIF($AL$8:$AL$17,"<="&$D20)+1)-INDEX($AL$8:$AL$17,COUNTIF($AL$8:$AL$17,"<="&$D20)))))+N($C$14)/100,"")))) | AJ20: =IF($B20="","",IF(ISNUMBER($AT20),$AT20,IF(ISNUMBER($D$10),$D$10,IFERROR(IF(COUNTIF($AL$8:$AL$17,"<="&$S20)=0,$AO$8,IF(COUNTIF($AL$8:$AL$17,"<="&$S20)>=COUNT($AL$8:$AL$17),INDEX($AO$8:$AO$17,COUNT($AL$8:$AL$17)),INDEX($AO$8:$AO$17,COUNTIF($AL$8:$AL$17,"<="&$S20))+(INDEX($AO$8:$AO$17,COUNTIF($AL$8:$AL$17,"<="&$S20)+1)-INDEX($AO$8:$AO$17,COUNTIF($AL$8:$AL$17,"<="&$S20)))*($S20-INDEX($AL$8:$AL$17,COUNTIF($AL$8:$AL$17,"<="&$S20)))/(INDEX($AL$8:$AL$17,COUNTIF($AL$8:$AL$17,"<="&$S20)+1)-INDEX($AL$8:$AL$17,COUNTIF($AL$8:$AL$17,"<="&$S20)))))+N($D$14)/100,"")))) | AP20: =IF($B20="","",$AQ$6&CHOOSE(MONTH($C20),"F","G","H","J","K","M","N","Q","U","V","X","Z")&RIGHT(YEAR($C20),1)&" Index") | AR20: =IF($AP20="","",BDP($AP20,"LAST_PRICE")) | AV20: =IF($L20="","",$O20-$C$49) | AW20: =IF($L20="","",$H20-$K20-$C$50-$C$45/10000*$C$9*$D20/365) | AX20: =IF($L20="","",IF($AV20>0,"SELL FUT / BUY CASH +"&TEXT($AV20,"0.0")&" pts net",IF($AW20>0,"BUY FUT / SHORT CASH +"&TEXT($AW20,"0.0")&" pts net","no edge after costs")))
B21: =IF('Div by Expiry'!$B15="","",'Div by Expiry'!$B15) | C21: =IF($B21="","",'Div by Expiry'!$C15) | D21: =IF($B21="","",'Div by Expiry'!$D15) | E21: =IF($B21="","",IF($AI21="","",$C$9*$AI21/100*$D21/$C$11)) | F21: =IF($B21="","",IF($C$13="N",'Div by Expiry'!$G15-IF($C$16="Y",0,'Div by Expiry'!$U38),IF($AI21="","",SUMPRODUCT('Div by Expiry'!$E$13:$E15,1+$AI21/100*($C21-(Expiries!$J$16:$J18+Expiries!$F$16:$F18)/2)/$C$11)-IF($C$16="Y",0,SUMPRODUCT('Div by Expiry'!$T$36:$T38,1+$AI21/100*($C21-(Expiries!$J$16:$J18+Expiries!$F$16:$F18)/2)/$C$11))))) | G21: =IF($B21="","",IF($C$13="N",'Div by Expiry'!$E38-IF($C$16="Y",0,'Div by Expiry'!$W38),IF($AI21="","",SUMPRODUCT('Div by Expiry'!$D$36:$D38,1+$AI21/100*($C21-(Expiries!$J$16:$J18+Expiries!$F$16:$F18)/2)/$C$11)-IF($C$16="Y",0,SUMPRODUCT('Div by Expiry'!$V$36:$V38,1+$AI21/100*($C21-(Expiries!$J$16:$J18+Expiries!$F$16:$F18)/2)/$C$11))))) | H21: =IF($B21="","",IF($E21="","",$C$9+$E21-$F21)) | I21: =IF($B21="","",IF($H21="","",$H21-$G21)) | J21: =IF($B21="","",IF($H21="","",$H21-$C$12/100*$G21)) | K21: =IF($B21="","",IF(ISNUMBER($AQ21),$AQ21,IF(ISNUMBER($AR21),$AR21,""))) | L21: =IF($B21="","",IF(N($K21)=0,"",IF($E21="","",$C$9+$E21-$K21))) | M21: =IF($L21="","",$L21-$F21) | N21: =IF($L21="","",IF($G21=0,"",$M21/$G21)) | O21: =IF($L21="","",$K21-$J21) | P21: =IF($L21="","",$O21/$C$9*10000) | R21: =IF($B21="","",'Div by Expiry'!$J15) | S21: =IF($B21="","",$R21-'Div by Expiry'!$C$7) | T21: =IF($B21="","",IF($AJ21="","",$D$9*$AJ21/100*$S21/$D$11)) | U21: =IF($B21="","",IF($C$13="N",'Div by Expiry'!$M15-IF($D$16="Y",0,'Div by Expiry'!$Y38),IF($AJ21="","",SUMPRODUCT('Div by Expiry'!$K$13:$K15,1+$AJ21/100*($R21-(Expiries!$K$16:$K18+Expiries!$I$16:$I18)/2)/$D$11)-IF($D$16="Y",0,SUMPRODUCT('Div by Expiry'!$X$36:$X38,1+$AJ21/100*($R21-(Expiries!$K$16:$K18+Expiries!$I$16:$I18)/2)/$D$11))))) | V21: =IF($B21="","",IF($C$13="N",'Div by Expiry'!$J38-IF($D$16="Y",0,'Div by Expiry'!$AA38),IF($AJ21="","",SUMPRODUCT('Div by Expiry'!$I$36:$I38,1+$AJ21/100*($R21-(Expiries!$K$16:$K18+Expiries!$I$16:$I18)/2)/$D$11)-IF($D$16="Y",0,SUMPRODUCT('Div by Expiry'!$Z$36:$Z38,1+$AJ21/100*($R21-(Expiries!$K$16:$K18+Expiries!$I$16:$I18)/2)/$D$11))))) | W21: =IF($B21="","",IF($T21="","",$D$9+$T21-$U21)) | X21: =IF($B21="","",IF($W21="","",$W21-$V21)) | Y21: =IF($B21="","",IF($W21="","",$W21-$D$12/100*$V21)) | AA21: =IF($B21="","",IF(N($Z21)=0,"",IF($T21="","",$D$9+$T21-$Z21))) | AB21: =IF($AA21="","",$AA21-$U21) | AC21: =IF($AA21="","",IF($V21=0,"",$AB21/$V21)) | AD21: =IF($AA21="","",$Z21-$Y21) | AE21: =IF($AA21="","",$AD21/$D$9*10000) | AG21: =IF($N21="","",IF($AC21="","",($N21-$AC21)*100)) | AI21: =IF($B21="","",IF(ISNUMBER($AS21),$AS21,IF(ISNUMBER($C$10),$C$10,IFERROR(IF(COUNTIF($AL$8:$AL$17,"<="&$D21)=0,$AO$8,IF(COUNTIF($AL$8:$AL$17,"<="&$D21)>=COUNT($AL$8:$AL$17),INDEX($AO$8:$AO$17,COUNT($AL$8:$AL$17)),INDEX($AO$8:$AO$17,COUNTIF($AL$8:$AL$17,"<="&$D21))+(INDEX($AO$8:$AO$17,COUNTIF($AL$8:$AL$17,"<="&$D21)+1)-INDEX($AO$8:$AO$17,COUNTIF($AL$8:$AL$17,"<="&$D21)))*($D21-INDEX($AL$8:$AL$17,COUNTIF($AL$8:$AL$17,"<="&$D21)))/(INDEX($AL$8:$AL$17,COUNTIF($AL$8:$AL$17,"<="&$D21)+1)-INDEX($AL$8:$AL$17,COUNTIF($AL$8:$AL$17,"<="&$D21)))))+N($C$14)/100,"")))) | AJ21: =IF($B21="","",IF(ISNUMBER($AT21),$AT21,IF(ISNUMBER($D$10),$D$10,IFERROR(IF(COUNTIF($AL$8:$AL$17,"<="&$S21)=0,$AO$8,IF(COUNTIF($AL$8:$AL$17,"<="&$S21)>=COUNT($AL$8:$AL$17),INDEX($AO$8:$AO$17,COUNT($AL$8:$AL$17)),INDEX($AO$8:$AO$17,COUNTIF($AL$8:$AL$17,"<="&$S21))+(INDEX($AO$8:$AO$17,COUNTIF($AL$8:$AL$17,"<="&$S21)+1)-INDEX($AO$8:$AO$17,COUNTIF($AL$8:$AL$17,"<="&$S21)))*($S21-INDEX($AL$8:$AL$17,COUNTIF($AL$8:$AL$17,"<="&$S21)))/(INDEX($AL$8:$AL$17,COUNTIF($AL$8:$AL$17,"<="&$S21)+1)-INDEX($AL$8:$AL$17,COUNTIF($AL$8:$AL$17,"<="&$S21)))))+N($D$14)/100,"")))) | AP21: =IF($B21="","",$AQ$6&CHOOSE(MONTH($C21),"F","G","H","J","K","M","N","Q","U","V","X","Z")&RIGHT(YEAR($C21),1)&" Index") | AR21: =IF($AP21="","",BDP($AP21,"LAST_PRICE")) | AV21: =IF($L21="","",$O21-$C$49) | AW21: =IF($L21="","",$H21-$K21-$C$50-$C$45/10000*$C$9*$D21/365) | AX21: =IF($L21="","",IF($AV21>0,"SELL FUT / BUY CASH +"&TEXT($AV21,"0.0")&" pts net",IF($AW21>0,"BUY FUT / SHORT CASH +"&TEXT($AW21,"0.0")&" pts net","no edge after costs")))
