Workbook
Name VAL_DATE: Summary!$C$11
Name YEAR_Y: Summary!$C$12
Name INC_SPECIALS: Summary!$C$13
Name RMB_CROSS: Summary!$C$14
Name HORIZON_DT: Summary!$C$15
Name PULL_FUND: Summary!$C$16
Name HIST_FROM: Summary!$C$18
Name HIST_TO: Summary!$D$18
Name OV_SWITCH: Override!$C$4
Name GRID_FROM: Grids!$D$5
Name GRID_TO: Grids!$D$6
Name VAL_SERIAL: Grids!$D$7
Name REALIZED_TO: Grids!$D$8
Name PROJ_FROM: Grids!$D$9
Name PEND_FROM: Pending!$F$4
Name PEND_TO: Pending!$H$4
Name FLD_PROJ: 'Field Check'!$C$6
Name FLD_HIST: 'Field Check'!$C$7
Name FLD_CCY: 'Field Check'!$C$8
Name FLD_DPS12M: 'Field Check'!$C$9
Name FLD_YLD12M: 'Field Check'!$C$10
Name EPS_FIELD: 'Field Check'!$C$15
Name YR_OVERRIDE: 'Field Check'!$C$16
Name PAYOUT_FIELD: 'Field Check'!$C$17
Name NDEBITDA_FIELD: 'Field Check'!$C$18
Name EBINT_FIELD: 'Field Check'!$C$19
Name NDE_FIELD: 'Field Check'!$C$20
Name BUYBACK_QUERY: 'Field Check'!$C$21
Name FCF_FIELD: 'Field Check'!$C$24
Name BESTEPS_FIELD: 'Field Check'!$C$25
Name BESTDPS_FIELD: 'Field Check'!$C$26
Name FWD_OVERRIDE: 'Field Check'!$C$27
Name TYPE1: 'Field Check'!$C$30
Name TYPE2: 'Field Check'!$C$31
Name TYPE3: 'Field Check'!$C$32
Name TYPE4: 'Field Check'!$C$33
Name SPECIAL_LBL: 'Field Check'!$C$34
Name OVR_TICKERS: Override!$B$12:$B$71
Name OVR_BASE: Override!$D$12:$D$71
Name OVR_LOW: Override!$E$12:$E$71
Name OVR_HIGH: Override!$F$12:$F$71

Sheet Field Check
B1: FIELD MNEMONIC TESTER & CONFIG
B2: Every mnemonic, query and type label lives on this tab - fix one here and the whole book follows. Green = verified on YOUR terminal. Amber = candidate.
B3: Test ticker | C3: 700 HK Equity
B4: WHEN SOMETHING BREAKS: 1) the HEALTH strip on Summary 2) the status column E below 3) the two live samples at the bottom - a changed spill shape shows there instantly.
B5: CONFIRMED - dividends & members
B6: Projected dividends (BDS) | C6: BDVD_ALL_PROJECTIONS | F6: Columns: Projected Declared / Ex-Date / Amount (the calendar pulls just these three). The declared date is filled even for far forecasts - ANNOUNCED means it has already passed.
B7: Dividend history (BDS) | C7: DVD_HIST_ALL | F7: Columns: Declared / Ex / Record / Payable / AMOUNT (5th) / Frequency / Type.
B8: Dividend currency (BDP) | C8: EQY_DVD_CRNCY | F8: Feeds the FX-to-HKD column.
B9: DPS 12M (BDP) | C9: EQY_DVD_SH_12M | F9: Reference + the divisor check on Summary.
B10: Yield 12M (BDP) | C10: EQY_DVD_YLD_12M | F10: Reference; also read at index level on Summary.
B11: GICS sector (BDP) | C11: GICS_SECTOR_NAME | F11: Drives every sector rollup and the Override view.
B12: Name (BDP) | C12: NAME
B14: CONFIRMED - fundamentals (verified on your terminal run)
B15: EPS by fiscal year (BDP) | C15: IS_EPS | F15: With the year override below. Tested OK.
B16: fiscal-year override name | C16: EQY_FUND_YEAR
B17: Payout by fiscal year (BDP) | C17: DVD_PAYOUT_RATIO | F17: Fiscal basis - DPS and EPS on the same clock. Tested OK.
B18: Net debt / EBITDA (BDP) | C18: NET_DEBT_TO_EBITDA | F18: Tested OK.
B19: EBITDA / interest (BDP) | C19: EBITDA_TO_INTEREST_EXPN | F19: Tested OK.
B20: Net debt / equity (BDH, 5Y) | C20: NET_DEBT_TO_SHRHLDR_EQTY | F20: Your working BDH pull (note _EQTY): five rows of date + value per stock on Fund History.
B21: Buyback yield by year (BQL) | C21: dropna((bs_tot_val_of_shares_repurchased(fpt=ltm)/cur_mkt_cap())*100, true) | F21: Your working BQL query: LTM buybacks / market cap, yearly, per stock on Fund History.
B23: CANDIDATES - check column E after a refresh | D23: live result | E23: status
B24: FCF yield (BDP) | C24: FREE_CASH_FLOW_YIELD | D24: =BDP($C$3,$C$24) | E24: =IF(ISNUMBER($D$24),"OK","check field") | F24: Came back N/A on the test name - the field exists but may need a different basis. Alternates: CF_FREE_CASH_FLOW_YIELD, FCF_YIELD.
B25: Forward EPS (BDP) | C25: BEST_EPS | D25: =BDP($C$3,$C$25,$C$27,TEXT(MOD(Summary!$C$12,100),"00")&"Y") | E25: =IF(ISNUMBER($D$25),"OK","check field") | F25: Consensus EPS for year Y via the period override below.
B26: Forward DPS (BDP) | C26: BEST_DPS | D26: =BDP($C$3,$C$26,$C$27,TEXT(MOD(Summary!$C$12,100),"00")&"Y") | E26: =IF(ISNUMBER($D$26),"OK","check field") | F26: Consensus DPS for year Y - sits beside the model's own number on Fundamentals.
B27: forward period override name | C27: BEST_FPERIOD_OVERRIDE | F27: e.g. 26Y = fiscal 2026. Alternate: BEST_FPERIOD_OVR.
B29: DIVIDEND TYPES THAT COUNT AS CASH (anything not listed is ignored) | F29: Seen in your data and EXCLUDED by omission: Spinoff, Bonus, Stock Split, Rights Issue, Entitlement, Omitted, Discontinued - none are cash dividends.
B30: Cash type 1 | C30: Final
B31: Cash type 2 | C31: Interim
B32: Cash type 3 | C32: Regular Cash
B33: Cash type 4 | C33: Return of Capital | F33: Cash to holders - blank this cell to exclude it.
B34: Special label | C34: Special Cash | F34: Counted only when the specials switch on Summary is Y.
B36: LIVE SAMPLE 1 - projections, FULL width (the calendar itself pulls only columns 1-3)
C37: =BDS($C$3,$C$6,"headers=y","startcol=1","endcol=7","dir=h")
B45: LIVE SAMPLE 2 - dividend history (7 rows: the amount is the 5th)
C46: =BDS($C$3,$C$7,"headers=y","startcol=1","endcol=7","dir=h","DVD_START_DT",Summary!$C$18,"DVD_END_DT",Summary!$D$18)
B55: YOUR BQL QUERY - reference
C56: '=@BQL.QUERY(AC16&AC17,"showallcols=t, showheaders=f, xlfill=b","cols=10;rows=1")
C57: let(#div=dividends(offset=1, status=TBA);#hastba=count(#div().status);) get(groupsort(#div,sortby=#div().ex_date,order=asc)) for(filter(members('HSI Index'),#hastba>0))
B59: Leave the space right of both samples clear - they spill as far as they need.

Sheet Summary
B1: HK DIVIDEND FUTURES MODEL - HSI / HSTECH / HSCEI
B2: Full-year index dividend points (what has gone ex + what is still to come) against the dividend futures. The year is the contract - there is no monthly ladder.
B3: HEALTH | C3: =IF(N(HSI!$L$2)=0,"paste quantities + divisor on the HSI tab",IF(ISNUMBER(HSI!$B$3)=FALSE,"divisor missing (HSI B3)",IF(N(HSI!$Y$5)=0,"waiting for prices - refresh on the terminal",IF(ABS(C48-1)>0.02,"UNITS OFF - multiply quantities by ~"&TEXT(C48,"#,##0"),IF(C55>0,"calendar window overflow - widen it",IF(C53>0,C53&" amount(s) TBA - consider overriding","OK")))))) | D3: =IF(N(HSTECH!$L$2)=0,"paste quantities + divisor on the HSTECH tab",IF(ISNUMBER(HSTECH!$B$3)=FALSE,"divisor missing (HSTECH B3)",IF(N(HSTECH!$Y$5)=0,"waiting for prices - refresh on the terminal",IF(ABS(D48-1)>0.02,"UNITS OFF - multiply quantities by ~"&TEXT(D48,"#,##0"),IF(D55>0,"calendar window overflow - widen it",IF(D53>0,D53&" amount(s) TBA - consider overriding","OK")))))) | E3: =IF(N(HSCEI!$L$2)=0,"paste quantities + divisor on the HSCEI tab",IF(ISNUMBER(HSCEI!$B$3)=FALSE,"divisor missing (HSCEI B3)",IF(N(HSCEI!$Y$5)=0,"waiting for prices - refresh on the terminal",IF(ABS(E48-1)>0.02,"UNITS OFF - multiply quantities by ~"&TEXT(E48,"#,##0"),IF(E55>0,"calendar window overflow - widen it",IF(E53>0,E53&" amount(s) TBA - consider overriding","OK")))))) | G3: <- these three cells always name the next thing to fix. When all three say OK, the model is trustworthy.
B4: START HERE
B5: 1 | C5: Paste BASKET QUANTITY into column B and the INDEX DIVISOR into B3 on the HSI, HSTECH and HSCEI tabs (blue cells). Quantity and divisor must be in CONSISTENT units - the SCALE FACTOR row in CHECKS below tells you instantly if they are not, and by how much.
B6: 2 | C6: Set the control block below, then enter your futures tickers in the MODEL block (or just type the quote you see).
B7: 3 | C7: On a Bloomberg terminal press Ctrl+Alt+F9 and wait - the first refresh is a few thousand requests. Set 'Pull fundamentals' to N for a fast dividends-only refresh.
B8: 4 | C8: Read the CHECKS block at the bottom before you quote a gap.
B10: CONTROL
B11: Valuation date | C11: =TODAY() | G11: Today by default. Type a date to freeze the study.
B12: Year (Y) - the futures year | C12: =YEAR($C$11) | G12: 2026 prices the Dec26 contract. 2027 models next year (realized empties, projections fill it). A past year gives the realized outcome.
B13: Include special dividends? | C13: Y | G13: Applies to REALIZED dividends (history carries a type). Bloomberg projections carry no type, so projected specials cannot be split out - they are always included.
B14: RMB cross for CNY dividends | C14: CNY | G14: CNY or CNH - which cross converts RMB-declared dividends into HKD.
B15: Pending list horizon | C15: =DATE($C$12,12,31) | G15: Pending shows every event with an ex-date after the valuation date up to here.
B16: Pull fundamentals? (Y/N) | C16: Y | G16: N blanks the EPS / payout / forward / buyback / leverage requests (~3,500 of them). The dividend model itself never needs them.
B17: Overrides | C17: =IF(Override!$C$4="ON","ON - "&Override!$E$4&" stock(s) set - the model uses YOUR numbers there.","OFF - pure Bloomberg projections.")
B18: History pull window (auto) | C18: =TEXT(DATE($C$12-5,1,1),"yyyymmdd") | D18: =TEXT(MAX($C$11,DATE($C$12,12,31)),"yyyymmdd") | G18: Five full years before Y plus the year itself - feeds the model and the 5-year fundamentals.
B20: MODEL vs FUTURES (index dividend points for year Y)
C21: HSI | D21: HSTECH | E21: HSCEI | G21: Points are index points: basket qty x FX-to-HKD x DPS / divisor.
B22: Index ticker | C22: HSI Index | D22: HSTECH Index | E22: HSCEI Index
B23: Index level | C23: =IF($C$22="","",BDP($C$22,"PX_LAST")) | D23: =IF($D$22="","",BDP($D$22,"PX_LAST")) | E23: =IF($E$22="","",BDP($E$22,"PX_LAST"))
B25: Realized so far (pts) | C25: =HSI!$O$5 | D25: =HSTECH!$O$5 | E25: =HSCEI!$O$5 | G25: Ex-dates from 1 Jan of Y to the valuation date - fact, never overridden. Cash dividend types only (no spinoffs / scrip - see the type list on Field Check).
B26: Still to come - Bloomberg (pts) | C26: =HSI!$W$5 | D26: =HSTECH!$W$5 | E26: =HSCEI!$W$5
B27: Still to come - EFFECTIVE (pts) | C27: =HSI!$P$5 | D27: =HSTECH!$P$5 | E27: =HSCEI!$P$5
B28: YEAR TOTAL - base (pts) | C28: =HSI!$Q$5 | D28: =HSTECH!$Q$5 | E28: =HSCEI!$Q$5
B29: your LOW case (pts) | C29: =HSI!$R$5 | D29: =HSTECH!$R$5 | E29: =HSCEI!$R$5
B30: your HIGH case (pts) | C30: =HSI!$S$5 | D30: =HSTECH!$S$5 | E30: =HSCEI!$S$5
B31: Implied index dividend yield | C31: =IFERROR(C28/C23,"") | D31: =IFERROR(D28/D23,"") | E31: =IFERROR(E28/E23,"")
B33: Futures ticker
B34: Futures price (Bloomberg) | C34: =IF($C$33="","",BDP($C$33,"PX_LAST")) | D34: =IF($D$33="","",BDP($D$33,"PX_LAST")) | E34: =IF($E$33="","",BDP($E$33,"PX_LAST"))
B35: Futures quote - type it yourself
B36: FUTURES USED | C36: =IF(ISNUMBER(C35),C35,IF(ISNUMBER(C34),C34,"")) | D36: =IF(ISNUMBER(D35),D35,IF(ISNUMBER(D34),D34,"")) | E36: =IF(ISNUMBER(E35),E35,IF(ISNUMBER(E34),E34,""))
B37: GAP model - futures (pts) | C37: =IF(C36="","",C28-C36) | D37: =IF(D36="","",D28-D36) | E37: =IF(E36="","",E28-E36) | G37: Positive = your model sees MORE dividends than the futures pay for. Read the TBA line in CHECKS before quoting it.
B38: Gap (% of futures) | C38: =IF(C36="","",IFERROR(C37/C36,"")) | D38: =IF(D36="","",IFERROR(D37/D36,"")) | E38: =IF(E36="","",IFERROR(E37/E36,""))
B39: Where the futures sit | C39: =IF(C36="","",IF((C36>=C29)*(C36<=C30)>0,"inside your low-high range",IF(C36<C29,"BELOW your low - cheap vs you","ABOVE your high - rich vs you"))) | D39: =IF(D36="","",IF((D36>=D29)*(D36<=D30)>0,"inside your low-high range",IF(D36<D29,"BELOW your low - cheap vs you","ABOVE your high - rich vs you"))) | E39: =IF(E36="","",IF((E36>=E29)*(E36<=E30)>0,"inside your low-high range",IF(E36<E29,"BELOW your low - cheap vs you","ABOVE your high - rich vs you")))
B41: CHECKS (read these before trusting the gap)
B42: Members returned | C42: =HSI!$H$2 | D42: =HSTECH!$H$2 | E42: =HSCEI!$H$2 | G42: Short of the real membership means the BDS pull was cut off.
B43: Basket quantities pasted | C43: =HSI!$L$2 | D43: =HSTECH!$L$2 | E43: =HSCEI!$L$2 | G43: Should equal members.
B44: Members with NO quantity | C44: =HSI!$P$2 | D44: =HSTECH!$P$2 | E44: =HSCEI!$P$2 | G44: Each one contributes zero points.
B45: Divisor entered | C45: =IF(ISNUMBER(HSI!$B$3),"OK","MISSING") | D45: =IF(ISNUMBER(HSTECH!$B$3),"OK","MISSING") | E45: =IF(ISNUMBER(HSCEI!$B$3),"OK","MISSING") | G45: Without it every points column is blank.
...

Sheet Pending
B1: PENDING DIVIDENDS - EVERYTHING STILL TO GO EX, SORTED BY DATE
B2: Ex-dates after the valuation date, up to the horizon. Amount TBA counts as ZERO until you override that stock.
B4: Horizon | C4: =HORIZON_DT | E4: thresholds -> | F4: =(VAL_DATE+1)*1000000000 | H4: =(HORIZON_DT+1)*1000000000 | I4: =Summary!$C$17
B6: Hang Seng Index (HSI)
B7: Events pending | C7: =COUNTIFS(Grids!$EE$12:$GQ$111,">="&PEND_FROM,Grids!$EE$12:$GQ$111,"<"&PEND_TO) | D7: =IF($C$7>300,"LIST TRUNCATED - showing the first 300; the model still counts all of them.","all listed below") | L7: offset | M7: =COUNTIF(Grids!$EE$12:$GQ$111,"<"&PEND_FROM)
B9: Ex-date | C9: Ticker | D9: Name | E9: DPS (declared ccy) | F9: CCY | G9: Index pts | H9: Cumulative pts | I9: Status | J9: Your override? | L9: engine
B10: =IF($L10="","",$M10) | C10: =IF($L10="","",INDEX(HSI!$C$7:$C$106,$N10)) | D10: =IF($L10="","",INDEX(HSI!$D$7:$D$106,$N10)) | E10: =IF($L10="","",IF($P10=0,"TBA",IFERROR(INDEX(Grids!$C$12:$BO$111,$N10,$O10),"-"))) | F10: =IF($L10="","",INDEX(HSI!$F$7:$F$106,$N10)) | G10: =IF($L10="","",IF($P10=0,"TBA",IFERROR(INDEX(Grids!$BQ$12:$EC$111,$N10,$O10),"-"))) | H10: =IF($L10="","",SUM($G$10:$G10)) | I10: =IF($L10="","",IF(INT(($L10-INT($L10/10000000)*10000000)/1000000)=0,"Bloomberg projection",IF($P10=1,"ANNOUNCED","ANNOUNCED - amount TBA"))) | J10: =IF($L10="","",IF((OV_SWITCH="ON")*(COUNTIFS(OVR_TICKERS,INDEX(HSI!$C$7:$C$106,$N10),OVR_BASE,">=0")>0)>0,"stock overridden","")) | L10: =IFERROR(IF(SMALL(Grids!$EE$12:$GQ$111,$M$7+1)>=PEND_TO,"",SMALL(Grids!$EE$12:$GQ$111,$M$7+1)),"") | M10: =IF($L10="","",INT($L10/1000000000)) | N10: =IF($L10="","",INT(($L10-INT($L10/1000000)*1000000)/1000)) | O10: =IF($L10="","",$L10-INT($L10/1000)*1000) | P10: =IF($L10="","",INT(($L10-INT($L10/1000000000)*1000000000)/100000000))
B11: =IF($L11="","",$M11) | C11: =IF($L11="","",INDEX(HSI!$C$7:$C$106,$N11)) | D11: =IF($L11="","",INDEX(HSI!$D$7:$D$106,$N11)) | E11: =IF($L11="","",IF($P11=0,"TBA",IFERROR(INDEX(Grids!$C$12:$BO$111,$N11,$O11),"-"))) | F11: =IF($L11="","",INDEX(HSI!$F$7:$F$106,$N11)) | G11: =IF($L11="","",IF($P11=0,"TBA",IFERROR(INDEX(Grids!$BQ$12:$EC$111,$N11,$O11),"-"))) | H11: =IF($L11="","",SUM($G$10:$G11)) | I11: =IF($L11="","",IF(INT(($L11-INT($L11/10000000)*10000000)/1000000)=0,"Bloomberg projection",IF($P11=1,"ANNOUNCED","ANNOUNCED - amount TBA"))) | J11: =IF($L11="","",IF((OV_SWITCH="ON")*(COUNTIFS(OVR_TICKERS,INDEX(HSI!$C$7:$C$106,$N11),OVR_BASE,">=0")>0)>0,"stock overridden","")) | L11: =IFERROR(IF(SMALL(Grids!$EE$12:$GQ$111,$M$7+2)>=PEND_TO,"",SMALL(Grids!$EE$12:$GQ$111,$M$7+2)),"") | M11: =IF($L11="","",INT($L11/1000000000)) | N11: =IF($L11="","",INT(($L11-INT($L11/1000000)*1000000)/1000)) | O11: =IF($L11="","",$L11-INT($L11/1000)*1000) | P11: =IF($L11="","",INT(($L11-INT($L11/1000000000)*1000000000)/100000000))
B12: =IF($L12="","",$M12) | C12: =IF($L12="","",INDEX(HSI!$C$7:$C$106,$N12)) | D12: =IF($L12="","",INDEX(HSI!$D$7:$D$106,$N12)) | E12: =IF($L12="","",IF($P12=0,"TBA",IFERROR(INDEX(Grids!$C$12:$BO$111,$N12,$O12),"-"))) | F12: =IF($L12="","",INDEX(HSI!$F$7:$F$106,$N12)) | G12: =IF($L12="","",IF($P12=0,"TBA",IFERROR(INDEX(Grids!$BQ$12:$EC$111,$N12,$O12),"-"))) | H12: =IF($L12="","",SUM($G$10:$G12)) | I12: =IF($L12="","",IF(INT(($L12-INT($L12/10000000)*10000000)/1000000)=0,"Bloomberg projection",IF($P12=1,"ANNOUNCED","ANNOUNCED - amount TBA"))) | J12: =IF($L12="","",IF((OV_SWITCH="ON")*(COUNTIFS(OVR_TICKERS,INDEX(HSI!$C$7:$C$106,$N12),OVR_BASE,">=0")>0)>0,"stock overridden","")) | L12: =IFERROR(IF(SMALL(Grids!$EE$12:$GQ$111,$M$7+3)>=PEND_TO,"",SMALL(Grids!$EE$12:$GQ$111,$M$7+3)),"") | M12: =IF($L12="","",INT($L12/1000000000)) | N12: =IF($L12="","",INT(($L12-INT($L12/1000000)*1000000)/1000)) | O12: =IF($L12="","",$L12-INT($L12/1000)*1000) | P12: =IF($L12="","",INT(($L12-INT($L12/1000000000)*1000000000)/100000000))
B13: =IF($L13="","",$M13) | C13: =IF($L13="","",INDEX(HSI!$C$7:$C$106,$N13)) | D13: =IF($L13="","",INDEX(HSI!$D$7:$D$106,$N13)) | E13: =IF($L13="","",IF($P13=0,"TBA",IFERROR(INDEX(Grids!$C$12:$BO$111,$N13,$O13),"-"))) | F13: =IF($L13="","",INDEX(HSI!$F$7:$F$106,$N13)) | G13: =IF($L13="","",IF($P13=0,"TBA",IFERROR(INDEX(Grids!$BQ$12:$EC$111,$N13,$O13),"-"))) | H13: =IF($L13="","",SUM($G$10:$G13)) | I13: =IF($L13="","",IF(INT(($L13-INT($L13/10000000)*10000000)/1000000)=0,"Bloomberg projection",IF($P13=1,"ANNOUNCED","ANNOUNCED - amount TBA"))) | J13: =IF($L13="","",IF((OV_SWITCH="ON")*(COUNTIFS(OVR_TICKERS,INDEX(HSI!$C$7:$C$106,$N13),OVR_BASE,">=0")>0)>0,"stock overridden","")) | L13: =IFERROR(IF(SMALL(Grids!$EE$12:$GQ$111,$M$7+4)>=PEND_TO,"",SMALL(Grids!$EE$12:$GQ$111,$M$7+4)),"") | M13: =IF($L13="","",INT($L13/1000000000)) | N13: =IF($L13="","",INT(($L13-INT($L13/1000000)*1000000)/1000)) | O13: =IF($L13="","",$L13-INT($L13/1000)*1000) | P13: =IF($L13="","",INT(($L13-INT($L13/1000000000)*1000000000)/100000000))
B14: =IF($L14="","",$M14) | C14: =IF($L14="","",INDEX(HSI!$C$7:$C$106,$N14)) | D14: =IF($L14="","",INDEX(HSI!$D$7:$D$106,$N14)) | E14: =IF($L14="","",IF($P14=0,"TBA",IFERROR(INDEX(Grids!$C$12:$BO$111,$N14,$O14),"-"))) | F14: =IF($L14="","",INDEX(HSI!$F$7:$F$106,$N14)) | G14: =IF($L14="","",IF($P14=0,"TBA",IFERROR(INDEX(Grids!$BQ$12:$EC$111,$N14,$O14),"-"))) | H14: =IF($L14="","",SUM($G$10:$G14)) | I14: =IF($L14="","",IF(INT(($L14-INT($L14/10000000)*10000000)/1000000)=0,"Bloomberg projection",IF($P14=1,"ANNOUNCED","ANNOUNCED - amount TBA"))) | J14: =IF($L14="","",IF((OV_SWITCH="ON")*(COUNTIFS(OVR_TICKERS,INDEX(HSI!$C$7:$C$106,$N14),OVR_BASE,">=0")>0)>0,"stock overridden","")) | L14: =IFERROR(IF(SMALL(Grids!$EE$12:$GQ$111,$M$7+5)>=PEND_TO,"",SMALL(Grids!$EE$12:$GQ$111,$M$7+5)),"") | M14: =IF($L14="","",INT($L14/1000000000)) | N14: =IF($L14="","",INT(($L14-INT($L14/1000000)*1000000)/1000)) | O14: =IF($L14="","",$L14-INT($L14/1000)*1000) | P14: =IF($L14="","",INT(($L14-INT($L14/1000000000)*1000000000)/100000000))
B15: =IF($L15="","",$M15) | C15: =IF($L15="","",INDEX(HSI!$C$7:$C$106,$N15)) | D15: =IF($L15="","",INDEX(HSI!$D$7:$D$106,$N15)) | E15: =IF($L15="","",IF($P15=0,"TBA",IFERROR(INDEX(Grids!$C$12:$BO$111,$N15,$O15),"-"))) | F15: =IF($L15="","",INDEX(HSI!$F$7:$F$106,$N15)) | G15: =IF($L15="","",IF($P15=0,"TBA",IFERROR(INDEX(Grids!$BQ$12:$EC$111,$N15,$O15),"-"))) | H15: =IF($L15="","",SUM($G$10:$G15)) | I15: =IF($L15="","",IF(INT(($L15-INT($L15/10000000)*10000000)/1000000)=0,"Bloomberg projection",IF($P15=1,"ANNOUNCED","ANNOUNCED - amount TBA"))) | J15: =IF($L15="","",IF((OV_SWITCH="ON")*(COUNTIFS(OVR_TICKERS,INDEX(HSI!$C$7:$C$106,$N15),OVR_BASE,">=0")>0)>0,"stock overridden","")) | L15: =IFERROR(IF(SMALL(Grids!$EE$12:$GQ$111,$M$7+6)>=PEND_TO,"",SMALL(Grids!$EE$12:$GQ$111,$M$7+6)),"") | M15: =IF($L15="","",INT($L15/1000000000)) | N15: =IF($L15="","",INT(($L15-INT($L15/1000000)*1000000)/1000)) | O15: =IF($L15="","",$L15-INT($L15/1000)*1000) | P15: =IF($L15="","",INT(($L15-INT($L15/1000000000)*1000000000)/100000000))
B16: =IF($L16="","",$M16) | C16: =IF($L16="","",INDEX(HSI!$C$7:$C$106,$N16)) | D16: =IF($L16="","",INDEX(HSI!$D$7:$D$106,$N16)) | E16: =IF($L16="","",IF($P16=0,"TBA",IFERROR(INDEX(Grids!$C$12:$BO$111,$N16,$O16),"-"))) | F16: =IF($L16="","",INDEX(HSI!$F$7:$F$106,$N16)) | G16: =IF($L16="","",IF($P16=0,"TBA",IFERROR(INDEX(Grids!$BQ$12:$EC$111,$N16,$O16),"-"))) | H16: =IF($L16="","",SUM($G$10:$G16)) | I16: =IF($L16="","",IF(INT(($L16-INT($L16/10000000)*10000000)/1000000)=0,"Bloomberg projection",IF($P16=1,"ANNOUNCED","ANNOUNCED - amount TBA"))) | J16: =IF($L16="","",IF((OV_SWITCH="ON")*(COUNTIFS(OVR_TICKERS,INDEX(HSI!$C$7:$C$106,$N16),OVR_BASE,">=0")>0)>0,"stock overridden","")) | L16: =IFERROR(IF(SMALL(Grids!$EE$12:$GQ$111,$M$7+7)>=PEND_TO,"",SMALL(Grids!$EE$12:$GQ$111,$M$7+7)),"") | M16: =IF($L16="","",INT($L16/1000000000)) | N16: =IF($L16="","",INT(($L16-INT($L16/1000000)*1000000)/1000)) | O16: =IF($L16="","",$L16-INT($L16/1000)*1000) | P16: =IF($L16="","",INT(($L16-INT($L16/1000000000)*1000000000)/100000000))
B17: =IF($L17="","",$M17) | C17: =IF($L17="","",INDEX(HSI!$C$7:$C$106,$N17)) | D17: =IF($L17="","",INDEX(HSI!$D$7:$D$106,$N17)) | E17: =IF($L17="","",IF($P17=0,"TBA",IFERROR(INDEX(Grids!$C$12:$BO$111,$N17,$O17),"-"))) | F17: =IF($L17="","",INDEX(HSI!$F$7:$F$106,$N17)) | G17: =IF($L17="","",IF($P17=0,"TBA",IFERROR(INDEX(Grids!$BQ$12:$EC$111,$N17,$O17),"-"))) | H17: =IF($L17="","",SUM($G$10:$G17)) | I17: =IF($L17="","",IF(INT(($L17-INT($L17/10000000)*10000000)/1000000)=0,"Bloomberg projection",IF($P17=1,"ANNOUNCED","ANNOUNCED - amount TBA"))) | J17: =IF($L17="","",IF((OV_SWITCH="ON")*(COUNTIFS(OVR_TICKERS,INDEX(HSI!$C$7:$C$106,$N17),OVR_BASE,">=0")>0)>0,"stock overridden","")) | L17: =IFERROR(IF(SMALL(Grids!$EE$12:$GQ$111,$M$7+8)>=PEND_TO,"",SMALL(Grids!$EE$12:$GQ$111,$M$7+8)),"") | M17: =IF($L17="","",INT($L17/1000000000)) | N17: =IF($L17="","",INT(($L17-INT($L17/1000000)*1000000)/1000)) | O17: =IF($L17="","",$L17-INT($L17/1000)*1000) | P17: =IF($L17="","",INT(($L17-INT($L17/1000000000)*1000000000)/100000000))
B18: =IF($L18="","",$M18) | C18: =IF($L18="","",INDEX(HSI!$C$7:$C$106,$N18)) | D18: =IF($L18="","",INDEX(HSI!$D$7:$D$106,$N18)) | E18: =IF($L18="","",IF($P18=0,"TBA",IFERROR(INDEX(Grids!$C$12:$BO$111,$N18,$O18),"-"))) | F18: =IF($L18="","",INDEX(HSI!$F$7:$F$106,$N18)) | G18: =IF($L18="","",IF($P18=0,"TBA",IFERROR(INDEX(Grids!$BQ$12:$EC$111,$N18,$O18),"-"))) | H18: =IF($L18="","",SUM($G$10:$G18)) | I18: =IF($L18="","",IF(INT(($L18-INT($L18/10000000)*10000000)/1000000)=0,"Bloomberg projection",IF($P18=1,"ANNOUNCED","ANNOUNCED - amount TBA"))) | J18: =IF($L18="","",IF((OV_SWITCH="ON")*(COUNTIFS(OVR_TICKERS,INDEX(HSI!$C$7:$C$106,$N18),OVR_BASE,">=0")>0)>0,"stock overridden","")) | L18: =IFERROR(IF(SMALL(Grids!$EE$12:$GQ$111,$M$7+9)>=PEND_TO,"",SMALL(Grids!$EE$12:$GQ$111,$M$7+9)),"") | M18: =IF($L18="","",INT($L18/1000000000)) | N18: =IF($L18="","",INT(($L18-INT($L18/1000000)*1000000)/1000)) | O18: =IF($L18="","",$L18-INT($L18/1000)*1000) | P18: =IF($L18="","",INT(($L18-INT($L18/1000000000)*1000000000)/100000000))
B19: =IF($L19="","",$M19) | C19: =IF($L19="","",INDEX(HSI!$C$7:$C$106,$N19)) | D19: =IF($L19="","",INDEX(HSI!$D$7:$D$106,$N19)) | E19: =IF($L19="","",IF($P19=0,"TBA",IFERROR(INDEX(Grids!$C$12:$BO$111,$N19,$O19),"-"))) | F19: =IF($L19="","",INDEX(HSI!$F$7:$F$106,$N19)) | G19: =IF($L19="","",IF($P19=0,"TBA",IFERROR(INDEX(Grids!$BQ$12:$EC$111,$N19,$O19),"-"))) | H19: =IF($L19="","",SUM($G$10:$G19)) | I19: =IF($L19="","",IF(INT(($L19-INT($L19/10000000)*10000000)/1000000)=0,"Bloomberg projection",IF($P19=1,"ANNOUNCED","ANNOUNCED - amount TBA"))) | J19: =IF($L19="","",IF((OV_SWITCH="ON")*(COUNTIFS(OVR_TICKERS,INDEX(HSI!$C$7:$C$106,$N19),OVR_BASE,">=0")>0)>0,"stock overridden","")) | L19: =IFERROR(IF(SMALL(Grids!$EE$12:$GQ$111,$M$7+10)>=PEND_TO,"",SMALL(Grids!$EE$12:$GQ$111,$M$7+10)),"") | M19: =IF($L19="","",INT($L19/1000000000)) | N19: =IF($L19="","",INT(($L19-INT($L19/1000000)*1000000)/1000)) | O19: =IF($L19="","",$L19-INT($L19/1000)*1000) | P19: =IF($L19="","",INT(($L19-INT($L19/1000000000)*1000000000)/100000000))
B20: =IF($L20="","",$M20) | C20: =IF($L20="","",INDEX(HSI!$C$7:$C$106,$N20)) | D20: =IF($L20="","",INDEX(HSI!$D$7:$D$106,$N20)) | E20: =IF($L20="","",IF($P20=0,"TBA",IFERROR(INDEX(Grids!$C$12:$BO$111,$N20,$O20),"-"))) | F20: =IF($L20="","",INDEX(HSI!$F$7:$F$106,$N20)) | G20: =IF($L20="","",IF($P20=0,"TBA",IFERROR(INDEX(Grids!$BQ$12:$EC$111,$N20,$O20),"-"))) | H20: =IF($L20="","",SUM($G$10:$G20)) | I20: =IF($L20="","",IF(INT(($L20-INT($L20/10000000)*10000000)/1000000)=0,"Bloomberg projection",IF($P20=1,"ANNOUNCED","ANNOUNCED - amount TBA"))) | J20: =IF($L20="","",IF((OV_SWITCH="ON")*(COUNTIFS(OVR_TICKERS,INDEX(HSI!$C$7:$C$106,$N20),OVR_BASE,">=0")>0)>0,"stock overridden","")) | L20: =IFERROR(IF(SMALL(Grids!$EE$12:$GQ$111,$M$7+11)>=PEND_TO,"",SMALL(Grids!$EE$12:$GQ$111,$M$7+11)),"") | M20: =IF($L20="","",INT($L20/1000000000)) | N20: =IF($L20="","",INT(($L20-INT($L20/1000000)*1000000)/1000)) | O20: =IF($L20="","",$L20-INT($L20/1000)*1000) | P20: =IF($L20="","",INT(($L20-INT($L20/1000000000)*1000000000)/100000000))
B21: =IF($L21="","",$M21) | C21: =IF($L21="","",INDEX(HSI!$C$7:$C$106,$N21)) | D21: =IF($L21="","",INDEX(HSI!$D$7:$D$106,$N21)) | E21: =IF($L21="","",IF($P21=0,"TBA",IFERROR(INDEX(Grids!$C$12:$BO$111,$N21,$O21),"-"))) | F21: =IF($L21="","",INDEX(HSI!$F$7:$F$106,$N21)) | G21: =IF($L21="","",IF($P21=0,"TBA",IFERROR(INDEX(Grids!$BQ$12:$EC$111,$N21,$O21),"-"))) | H21: =IF($L21="","",SUM($G$10:$G21)) | I21: =IF($L21="","",IF(INT(($L21-INT($L21/10000000)*10000000)/1000000)=0,"Bloomberg projection",IF($P21=1,"ANNOUNCED","ANNOUNCED - amount TBA"))) | J21: =IF($L21="","",IF((OV_SWITCH="ON")*(COUNTIFS(OVR_TICKERS,INDEX(HSI!$C$7:$C$106,$N21),OVR_BASE,">=0")>0)>0,"stock overridden","")) | L21: =IFERROR(IF(SMALL(Grids!$EE$12:$GQ$111,$M$7+12)>=PEND_TO,"",SMALL(Grids!$EE$12:$GQ$111,$M$7+12)),"") | M21: =IF($L21="","",INT($L21/1000000000)) | N21: =IF($L21="","",INT(($L21-INT($L21/1000000)*1000000)/1000)) | O21: =IF($L21="","",$L21-INT($L21/1000)*1000) | P21: =IF($L21="","",INT(($L21-INT($L21/1000000000)*1000000000)/100000000))
B22: =IF($L22="","",$M22) | C22: =IF($L22="","",INDEX(HSI!$C$7:$C$106,$N22)) | D22: =IF($L22="","",INDEX(HSI!$D$7:$D$106,$N22)) | E22: =IF($L22="","",IF($P22=0,"TBA",IFERROR(INDEX(Grids!$C$12:$BO$111,$N22,$O22),"-"))) | F22: =IF($L22="","",INDEX(HSI!$F$7:$F$106,$N22)) | G22: =IF($L22="","",IF($P22=0,"TBA",IFERROR(INDEX(Grids!$BQ$12:$EC$111,$N22,$O22),"-"))) | H22: =IF($L22="","",SUM($G$10:$G22)) | I22: =IF($L22="","",IF(INT(($L22-INT($L22/10000000)*10000000)/1000000)=0,"Bloomberg projection",IF($P22=1,"ANNOUNCED","ANNOUNCED - amount TBA"))) | J22: =IF($L22="","",IF((OV_SWITCH="ON")*(COUNTIFS(OVR_TICKERS,INDEX(HSI!$C$7:$C$106,$N22),OVR_BASE,">=0")>0)>0,"stock overridden","")) | L22: =IFERROR(IF(SMALL(Grids!$EE$12:$GQ$111,$M$7+13)>=PEND_TO,"",SMALL(Grids!$EE$12:$GQ$111,$M$7+13)),"") | M22: =IF($L22="","",INT($L22/1000000000)) | N22: =IF($L22="","",INT(($L22-INT($L22/1000000)*1000000)/1000)) | O22: =IF($L22="","",$L22-INT($L22/1000)*1000) | P22: =IF($L22="","",INT(($L22-INT($L22/1000000000)*1000000000)/100000000))
B23: =IF($L23="","",$M23) | C23: =IF($L23="","",INDEX(HSI!$C$7:$C$106,$N23)) | D23: =IF($L23="","",INDEX(HSI!$D$7:$D$106,$N23)) | E23: =IF($L23="","",IF($P23=0,"TBA",IFERROR(INDEX(Grids!$C$12:$BO$111,$N23,$O23),"-"))) | F23: =IF($L23="","",INDEX(HSI!$F$7:$F$106,$N23)) | G23: =IF($L23="","",IF($P23=0,"TBA",IFERROR(INDEX(Grids!$BQ$12:$EC$111,$N23,$O23),"-"))) | H23: =IF($L23="","",SUM($G$10:$G23)) | I23: =IF($L23="","",IF(INT(($L23-INT($L23/10000000)*10000000)/1000000)=0,"Bloomberg projection",IF($P23=1,"ANNOUNCED","ANNOUNCED - amount TBA"))) | J23: =IF($L23="","",IF((OV_SWITCH="ON")*(COUNTIFS(OVR_TICKERS,INDEX(HSI!$C$7:$C$106,$N23),OVR_BASE,">=0")>0)>0,"stock overridden","")) | L23: =IFERROR(IF(SMALL(Grids!$EE$12:$GQ$111,$M$7+14)>=PEND_TO,"",SMALL(Grids!$EE$12:$GQ$111,$M$7+14)),"") | M23: =IF($L23="","",INT($L23/1000000000)) | N23: =IF($L23="","",INT(($L23-INT($L23/1000000)*1000000)/1000)) | O23: =IF($L23="","",$L23-INT($L23/1000)*1000) | P23: =IF($L23="","",INT(($L23-INT($L23/1000000000)*1000000000)/100000000))
B24: =IF($L24="","",$M24) | C24: =IF($L24="","",INDEX(HSI!$C$7:$C$106,$N24)) | D24: =IF($L24="","",INDEX(HSI!$D$7:$D$106,$N24)) | E24: =IF($L24="","",IF($P24=0,"TBA",IFERROR(INDEX(Grids!$C$12:$BO$111,$N24,$O24),"-"))) | F24: =IF($L24="","",INDEX(HSI!$F$7:$F$106,$N24)) | G24: =IF($L24="","",IF($P24=0,"TBA",IFERROR(INDEX(Grids!$BQ$12:$EC$111,$N24,$O24),"-"))) | H24: =IF($L24="","",SUM($G$10:$G24)) | I24: =IF($L24="","",IF(INT(($L24-INT($L24/10000000)*10000000)/1000000)=0,"Bloomberg projection",IF($P24=1,"ANNOUNCED","ANNOUNCED - amount TBA"))) | J24: =IF($L24="","",IF((OV_SWITCH="ON")*(COUNTIFS(OVR_TICKERS,INDEX(HSI!$C$7:$C$106,$N24),OVR_BASE,">=0")>0)>0,"stock overridden","")) | L24: =IFERROR(IF(SMALL(Grids!$EE$12:$GQ$111,$M$7+15)>=PEND_TO,"",SMALL(Grids!$EE$12:$GQ$111,$M$7+15)),"") | M24: =IF($L24="","",INT($L24/1000000000)) | N24: =IF($L24="","",INT(($L24-INT($L24/1000000)*1000000)/1000)) | O24: =IF($L24="","",$L24-INT($L24/1000)*1000) | P24: =IF($L24="","",INT(($L24-INT($L24/1000000000)*1000000000)/100000000))
B25: =IF($L25="","",$M25) | C25: =IF($L25="","",INDEX(HSI!$C$7:$C$106,$N25)) | D25: =IF($L25="","",INDEX(HSI!$D$7:$D$106,$N25)) | E25: =IF($L25="","",IF($P25=0,"TBA",IFERROR(INDEX(Grids!$C$12:$BO$111,$N25,$O25),"-"))) | F25: =IF($L25="","",INDEX(HSI!$F$7:$F$106,$N25)) | G25: =IF($L25="","",IF($P25=0,"TBA",IFERROR(INDEX(Grids!$BQ$12:$EC$111,$N25,$O25),"-"))) | H25: =IF($L25="","",SUM($G$10:$G25)) | I25: =IF($L25="","",IF(INT(($L25-INT($L25/10000000)*10000000)/1000000)=0,"Bloomberg projection",IF($P25=1,"ANNOUNCED","ANNOUNCED - amount TBA"))) | J25: =IF($L25="","",IF((OV_SWITCH="ON")*(COUNTIFS(OVR_TICKERS,INDEX(HSI!$C$7:$C$106,$N25),OVR_BASE,">=0")>0)>0,"stock overridden","")) | L25: =IFERROR(IF(SMALL(Grids!$EE$12:$GQ$111,$M$7+16)>=PEND_TO,"",SMALL(Grids!$EE$12:$GQ$111,$M$7+16)),"") | M25: =IF($L25="","",INT($L25/1000000000)) | N25: =IF($L25="","",INT(($L25-INT($L25/1000000)*1000000)/1000)) | O25: =IF($L25="","",$L25-INT($L25/1000)*1000) | P25: =IF($L25="","",INT(($L25-INT($L25/1000000000)*1000000000)/100000000))
B26: =IF($L26="","",$M26) | C26: =IF($L26="","",INDEX(HSI!$C$7:$C$106,$N26)) | D26: =IF($L26="","",INDEX(HSI!$D$7:$D$106,$N26)) | E26: =IF($L26="","",IF($P26=0,"TBA",IFERROR(INDEX(Grids!$C$12:$BO$111,$N26,$O26),"-"))) | F26: =IF($L26="","",INDEX(HSI!$F$7:$F$106,$N26)) | G26: =IF($L26="","",IF($P26=0,"TBA",IFERROR(INDEX(Grids!$BQ$12:$EC$111,$N26,$O26),"-"))) | H26: =IF($L26="","",SUM($G$10:$G26)) | I26: =IF($L26="","",IF(INT(($L26-INT($L26/10000000)*10000000)/1000000)=0,"Bloomberg projection",IF($P26=1,"ANNOUNCED","ANNOUNCED - amount TBA"))) | J26: =IF($L26="","",IF((OV_SWITCH="ON")*(COUNTIFS(OVR_TICKERS,INDEX(HSI!$C$7:$C$106,$N26),OVR_BASE,">=0")>0)>0,"stock overridden","")) | L26: =IFERROR(IF(SMALL(Grids!$EE$12:$GQ$111,$M$7+17)>=PEND_TO,"",SMALL(Grids!$EE$12:$GQ$111,$M$7+17)),"") | M26: =IF($L26="","",INT($L26/1000000000)) | N26: =IF($L26="","",INT(($L26-INT($L26/1000000)*1000000)/1000)) | O26: =IF($L26="","",$L26-INT($L26/1000)*1000) | P26: =IF($L26="","",INT(($L26-INT($L26/1000000000)*1000000000)/100000000))
B27: =IF($L27="","",$M27) | C27: =IF($L27="","",INDEX(HSI!$C$7:$C$106,$N27)) | D27: =IF($L27="","",INDEX(HSI!$D$7:$D$106,$N27)) | E27: =IF($L27="","",IF($P27=0,"TBA",IFERROR(INDEX(Grids!$C$12:$BO$111,$N27,$O27),"-"))) | F27: =IF($L27="","",INDEX(HSI!$F$7:$F$106,$N27)) | G27: =IF($L27="","",IF($P27=0,"TBA",IFERROR(INDEX(Grids!$BQ$12:$EC$111,$N27,$O27),"-"))) | H27: =IF($L27="","",SUM($G$10:$G27)) | I27: =IF($L27="","",IF(INT(($L27-INT($L27/10000000)*10000000)/1000000)=0,"Bloomberg projection",IF($P27=1,"ANNOUNCED","ANNOUNCED - amount TBA"))) | J27: =IF($L27="","",IF((OV_SWITCH="ON")*(COUNTIFS(OVR_TICKERS,INDEX(HSI!$C$7:$C$106,$N27),OVR_BASE,">=0")>0)>0,"stock overridden","")) | L27: =IFERROR(IF(SMALL(Grids!$EE$12:$GQ$111,$M$7+18)>=PEND_TO,"",SMALL(Grids!$EE$12:$GQ$111,$M$7+18)),"") | M27: =IF($L27="","",INT($L27/1000000000)) | N27: =IF($L27="","",INT(($L27-INT($L27/1000000)*1000000)/1000)) | O27: =IF($L27="","",$L27-INT($L27/1000)*1000) | P27: =IF($L27="","",INT(($L27-INT($L27/1000000000)*1000000000)/100000000))
B28: =IF($L28="","",$M28) | C28: =IF($L28="","",INDEX(HSI!$C$7:$C$106,$N28)) | D28: =IF($L28="","",INDEX(HSI!$D$7:$D$106,$N28)) | E28: =IF($L28="","",IF($P28=0,"TBA",IFERROR(INDEX(Grids!$C$12:$BO$111,$N28,$O28),"-"))) | F28: =IF($L28="","",INDEX(HSI!$F$7:$F$106,$N28)) | G28: =IF($L28="","",IF($P28=0,"TBA",IFERROR(INDEX(Grids!$BQ$12:$EC$111,$N28,$O28),"-"))) | H28: =IF($L28="","",SUM($G$10:$G28)) | I28: =IF($L28="","",IF(INT(($L28-INT($L28/10000000)*10000000)/1000000)=0,"Bloomberg projection",IF($P28=1,"ANNOUNCED","ANNOUNCED - amount TBA"))) | J28: =IF($L28="","",IF((OV_SWITCH="ON")*(COUNTIFS(OVR_TICKERS,INDEX(HSI!$C$7:$C$106,$N28),OVR_BASE,">=0")>0)>0,"stock overridden","")) | L28: =IFERROR(IF(SMALL(Grids!$EE$12:$GQ$111,$M$7+19)>=PEND_TO,"",SMALL(Grids!$EE$12:$GQ$111,$M$7+19)),"") | M28: =IF($L28="","",INT($L28/1000000000)) | N28: =IF($L28="","",INT(($L28-INT($L28/1000000)*1000000)/1000)) | O28: =IF($L28="","",$L28-INT($L28/1000)*1000) | P28: =IF($L28="","",INT(($L28-INT($L28/1000000000)*1000000000)/100000000))
B29: =IF($L29="","",$M29) | C29: =IF($L29="","",INDEX(HSI!$C$7:$C$106,$N29)) | D29: =IF($L29="","",INDEX(HSI!$D$7:$D$106,$N29)) | E29: =IF($L29="","",IF($P29=0,"TBA",IFERROR(INDEX(Grids!$C$12:$BO$111,$N29,$O29),"-"))) | F29: =IF($L29="","",INDEX(HSI!$F$7:$F$106,$N29)) | G29: =IF($L29="","",IF($P29=0,"TBA",IFERROR(INDEX(Grids!$BQ$12:$EC$111,$N29,$O29),"-"))) | H29: =IF($L29="","",SUM($G$10:$G29)) | I29: =IF($L29="","",IF(INT(($L29-INT($L29/10000000)*10000000)/1000000)=0,"Bloomberg projection",IF($P29=1,"ANNOUNCED","ANNOUNCED - amount TBA"))) | J29: =IF($L29="","",IF((OV_SWITCH="ON")*(COUNTIFS(OVR_TICKERS,INDEX(HSI!$C$7:$C$106,$N29),OVR_BASE,">=0")>0)>0,"stock overridden","")) | L29: =IFERROR(IF(SMALL(Grids!$EE$12:$GQ$111,$M$7+20)>=PEND_TO,"",SMALL(Grids!$EE$12:$GQ$111,$M$7+20)),"") | M29: =IF($L29="","",INT($L29/1000000000)) | N29: =IF($L29="","",INT(($L29-INT($L29/1000000)*1000000)/1000)) | O29: =IF($L29="","",$L29-INT($L29/1000)*1000) | P29: =IF($L29="","",INT(($L29-INT($L29/1000000000)*1000000000)/100000000))
B30: =IF($L30="","",$M30) | C30: =IF($L30="","",INDEX(HSI!$C$7:$C$106,$N30)) | D30: =IF($L30="","",INDEX(HSI!$D$7:$D$106,$N30)) | E30: =IF($L30="","",IF($P30=0,"TBA",IFERROR(INDEX(Grids!$C$12:$BO$111,$N30,$O30),"-"))) | F30: =IF($L30="","",INDEX(HSI!$F$7:$F$106,$N30)) | G30: =IF($L30="","",IF($P30=0,"TBA",IFERROR(INDEX(Grids!$BQ$12:$EC$111,$N30,$O30),"-"))) | H30: =IF($L30="","",SUM($G$10:$G30)) | I30: =IF($L30="","",IF(INT(($L30-INT($L30/10000000)*10000000)/1000000)=0,"Bloomberg projection",IF($P30=1,"ANNOUNCED","ANNOUNCED - amount TBA"))) | J30: =IF($L30="","",IF((OV_SWITCH="ON")*(COUNTIFS(OVR_TICKERS,INDEX(HSI!$C$7:$C$106,$N30),OVR_BASE,">=0")>0)>0,"stock overridden","")) | L30: =IFERROR(IF(SMALL(Grids!$EE$12:$GQ$111,$M$7+21)>=PEND_TO,"",SMALL(Grids!$EE$12:$GQ$111,$M$7+21)),"") | M30: =IF($L30="","",INT($L30/1000000000)) | N30: =IF($L30="","",INT(($L30-INT($L30/1000000)*1000000)/1000)) | O30: =IF($L30="","",$L30-INT($L30/1000)*1000) | P30: =IF($L30="","",INT(($L30-INT($L30/1000000000)*1000000000)/100000000))
B31: =IF($L31="","",$M31) | C31: =IF($L31="","",INDEX(HSI!$C$7:$C$106,$N31)) | D31: =IF($L31="","",INDEX(HSI!$D$7:$D$106,$N31)) | E31: =IF($L31="","",IF($P31=0,"TBA",IFERROR(INDEX(Grids!$C$12:$BO$111,$N31,$O31),"-"))) | F31: =IF($L31="","",INDEX(HSI!$F$7:$F$106,$N31)) | G31: =IF($L31="","",IF($P31=0,"TBA",IFERROR(INDEX(Grids!$BQ$12:$EC$111,$N31,$O31),"-"))) | H31: =IF($L31="","",SUM($G$10:$G31)) | I31: =IF($L31="","",IF(INT(($L31-INT($L31/10000000)*10000000)/1000000)=0,"Bloomberg projection",IF($P31=1,"ANNOUNCED","ANNOUNCED - amount TBA"))) | J31: =IF($L31="","",IF((OV_SWITCH="ON")*(COUNTIFS(OVR_TICKERS,INDEX(HSI!$C$7:$C$106,$N31),OVR_BASE,">=0")>0)>0,"stock overridden","")) | L31: =IFERROR(IF(SMALL(Grids!$EE$12:$GQ$111,$M$7+22)>=PEND_TO,"",SMALL(Grids!$EE$12:$GQ$111,$M$7+22)),"") | M31: =IF($L31="","",INT($L31/1000000000)) | N31: =IF($L31="","",INT(($L31-INT($L31/1000000)*1000000)/1000)) | O31: =IF($L31="","",$L31-INT($L31/1000)*1000) | P31: =IF($L31="","",INT(($L31-INT($L31/1000000000)*1000000000)/100000000))
B32: =IF($L32="","",$M32) | C32: =IF($L32="","",INDEX(HSI!$C$7:$C$106,$N32)) | D32: =IF($L32="","",INDEX(HSI!$D$7:$D$106,$N32)) | E32: =IF($L32="","",IF($P32=0,"TBA",IFERROR(INDEX(Grids!$C$12:$BO$111,$N32,$O32),"-"))) | F32: =IF($L32="","",INDEX(HSI!$F$7:$F$106,$N32)) | G32: =IF($L32="","",IF($P32=0,"TBA",IFERROR(INDEX(Grids!$BQ$12:$EC$111,$N32,$O32),"-"))) | H32: =IF($L32="","",SUM($G$10:$G32)) | I32: =IF($L32="","",IF(INT(($L32-INT($L32/10000000)*10000000)/1000000)=0,"Bloomberg projection",IF($P32=1,"ANNOUNCED","ANNOUNCED - amount TBA"))) | J32: =IF($L32="","",IF((OV_SWITCH="ON")*(COUNTIFS(OVR_TICKERS,INDEX(HSI!$C$7:$C$106,$N32),OVR_BASE,">=0")>0)>0,"stock overridden","")) | L32: =IFERROR(IF(SMALL(Grids!$EE$12:$GQ$111,$M$7+23)>=PEND_TO,"",SMALL(Grids!$EE$12:$GQ$111,$M$7+23)),"") | M32: =IF($L32="","",INT($L32/1000000000)) | N32: =IF($L32="","",INT(($L32-INT($L32/1000000)*1000000)/1000)) | O32: =IF($L32="","",$L32-INT($L32/1000)*1000) | P32: =IF($L32="","",INT(($L32-INT($L32/1000000000)*1000000000)/100000000))
B33: =IF($L33="","",$M33) | C33: =IF($L33="","",INDEX(HSI!$C$7:$C$106,$N33)) | D33: =IF($L33="","",INDEX(HSI!$D$7:$D$106,$N33)) | E33: =IF($L33="","",IF($P33=0,"TBA",IFERROR(INDEX(Grids!$C$12:$BO$111,$N33,$O33),"-"))) | F33: =IF($L33="","",INDEX(HSI!$F$7:$F$106,$N33)) | G33: =IF($L33="","",IF($P33=0,"TBA",IFERROR(INDEX(Grids!$BQ$12:$EC$111,$N33,$O33),"-"))) | H33: =IF($L33="","",SUM($G$10:$G33)) | I33: =IF($L33="","",IF(INT(($L33-INT($L33/10000000)*10000000)/1000000)=0,"Bloomberg projection",IF($P33=1,"ANNOUNCED","ANNOUNCED - amount TBA"))) | J33: =IF($L33="","",IF((OV_SWITCH="ON")*(COUNTIFS(OVR_TICKERS,INDEX(HSI!$C$7:$C$106,$N33),OVR_BASE,">=0")>0)>0,"stock overridden","")) | L33: =IFERROR(IF(SMALL(Grids!$EE$12:$GQ$111,$M$7+24)>=PEND_TO,"",SMALL(Grids!$EE$12:$GQ$111,$M$7+24)),"") | M33: =IF($L33="","",INT($L33/1000000000)) | N33: =IF($L33="","",INT(($L33-INT($L33/1000000)*1000000)/1000)) | O33: =IF($L33="","",$L33-INT($L33/1000)*1000) | P33: =IF($L33="","",INT(($L33-INT($L33/1000000000)*1000000000)/100000000))
B34: =IF($L34="","",$M34) | C34: =IF($L34="","",INDEX(HSI!$C$7:$C$106,$N34)) | D34: =IF($L34="","",INDEX(HSI!$D$7:$D$106,$N34)) | E34: =IF($L34="","",IF($P34=0,"TBA",IFERROR(INDEX(Grids!$C$12:$BO$111,$N34,$O34),"-"))) | F34: =IF($L34="","",INDEX(HSI!$F$7:$F$106,$N34)) | G34: =IF($L34="","",IF($P34=0,"TBA",IFERROR(INDEX(Grids!$BQ$12:$EC$111,$N34,$O34),"-"))) | H34: =IF($L34="","",SUM($G$10:$G34)) | I34: =IF($L34="","",IF(INT(($L34-INT($L34/10000000)*10000000)/1000000)=0,"Bloomberg projection",IF($P34=1,"ANNOUNCED","ANNOUNCED - amount TBA"))) | J34: =IF($L34="","",IF((OV_SWITCH="ON")*(COUNTIFS(OVR_TICKERS,INDEX(HSI!$C$7:$C$106,$N34),OVR_BASE,">=0")>0)>0,"stock overridden","")) | L34: =IFERROR(IF(SMALL(Grids!$EE$12:$GQ$111,$M$7+25)>=PEND_TO,"",SMALL(Grids!$EE$12:$GQ$111,$M$7+25)),"") | M34: =IF($L34="","",INT($L34/1000000000)) | N34: =IF($L34="","",INT(($L34-INT($L34/1000000)*1000000)/1000)) | O34: =IF($L34="","",$L34-INT($L34/1000)*1000) | P34: =IF($L34="","",INT(($L34-INT($L34/1000000000)*1000000000)/100000000))
B35: =IF($L35="","",$M35) | C35: =IF($L35="","",INDEX(HSI!$C$7:$C$106,$N35)) | D35: =IF($L35="","",INDEX(HSI!$D$7:$D$106,$N35)) | E35: =IF($L35="","",IF($P35=0,"TBA",IFERROR(INDEX(Grids!$C$12:$BO$111,$N35,$O35),"-"))) | F35: =IF($L35="","",INDEX(HSI!$F$7:$F$106,$N35)) | G35: =IF($L35="","",IF($P35=0,"TBA",IFERROR(INDEX(Grids!$BQ$12:$EC$111,$N35,$O35),"-"))) | H35: =IF($L35="","",SUM($G$10:$G35)) | I35: =IF($L35="","",IF(INT(($L35-INT($L35/10000000)*10000000)/1000000)=0,"Bloomberg projection",IF($P35=1,"ANNOUNCED","ANNOUNCED - amount TBA"))) | J35: =IF($L35="","",IF((OV_SWITCH="ON")*(COUNTIFS(OVR_TICKERS,INDEX(HSI!$C$7:$C$106,$N35),OVR_BASE,">=0")>0)>0,"stock overridden","")) | L35: =IFERROR(IF(SMALL(Grids!$EE$12:$GQ$111,$M$7+26)>=PEND_TO,"",SMALL(Grids!$EE$12:$GQ$111,$M$7+26)),"") | M35: =IF($L35="","",INT($L35/1000000000)) | N35: =IF($L35="","",INT(($L35-INT($L35/1000000)*1000000)/1000)) | O35: =IF($L35="","",$L35-INT($L35/1000)*1000) | P35: =IF($L35="","",INT(($L35-INT($L35/1000000000)*1000000000)/100000000))
B36: =IF($L36="","",$M36) | C36: =IF($L36="","",INDEX(HSI!$C$7:$C$106,$N36)) | D36: =IF($L36="","",INDEX(HSI!$D$7:$D$106,$N36)) | E36: =IF($L36="","",IF($P36=0,"TBA",IFERROR(INDEX(Grids!$C$12:$BO$111,$N36,$O36),"-"))) | F36: =IF($L36="","",INDEX(HSI!$F$7:$F$106,$N36)) | G36: =IF($L36="","",IF($P36=0,"TBA",IFERROR(INDEX(Grids!$BQ$12:$EC$111,$N36,$O36),"-"))) | H36: =IF($L36="","",SUM($G$10:$G36)) | I36: =IF($L36="","",IF(INT(($L36-INT($L36/10000000)*10000000)/1000000)=0,"Bloomberg projection",IF($P36=1,"ANNOUNCED","ANNOUNCED - amount TBA"))) | J36: =IF($L36="","",IF((OV_SWITCH="ON")*(COUNTIFS(OVR_TICKERS,INDEX(HSI!$C$7:$C$106,$N36),OVR_BASE,">=0")>0)>0,"stock overridden","")) | L36: =IFERROR(IF(SMALL(Grids!$EE$12:$GQ$111,$M$7+27)>=PEND_TO,"",SMALL(Grids!$EE$12:$GQ$111,$M$7+27)),"") | M36: =IF($L36="","",INT($L36/1000000000)) | N36: =IF($L36="","",INT(($L36-INT($L36/1000000)*1000000)/1000)) | O36: =IF($L36="","",$L36-INT($L36/1000)*1000) | P36: =IF($L36="","",INT(($L36-INT($L36/1000000000)*1000000000)/100000000))
B37: =IF($L37="","",$M37) | C37: =IF($L37="","",INDEX(HSI!$C$7:$C$106,$N37)) | D37: =IF($L37="","",INDEX(HSI!$D$7:$D$106,$N37)) | E37: =IF($L37="","",IF($P37=0,"TBA",IFERROR(INDEX(Grids!$C$12:$BO$111,$N37,$O37),"-"))) | F37: =IF($L37="","",INDEX(HSI!$F$7:$F$106,$N37)) | G37: =IF($L37="","",IF($P37=0,"TBA",IFERROR(INDEX(Grids!$BQ$12:$EC$111,$N37,$O37),"-"))) | H37: =IF($L37="","",SUM($G$10:$G37)) | I37: =IF($L37="","",IF(INT(($L37-INT($L37/10000000)*10000000)/1000000)=0,"Bloomberg projection",IF($P37=1,"ANNOUNCED","ANNOUNCED - amount TBA"))) | J37: =IF($L37="","",IF((OV_SWITCH="ON")*(COUNTIFS(OVR_TICKERS,INDEX(HSI!$C$7:$C$106,$N37),OVR_BASE,">=0")>0)>0,"stock overridden","")) | L37: =IFERROR(IF(SMALL(Grids!$EE$12:$GQ$111,$M$7+28)>=PEND_TO,"",SMALL(Grids!$EE$12:$GQ$111,$M$7+28)),"") | M37: =IF($L37="","",INT($L37/1000000000)) | N37: =IF($L37="","",INT(($L37-INT($L37/1000000)*1000000)/1000)) | O37: =IF($L37="","",$L37-INT($L37/1000)*1000) | P37: =IF($L37="","",INT(($L37-INT($L37/1000000000)*1000000000)/100000000))
B38: =IF($L38="","",$M38) | C38: =IF($L38="","",INDEX(HSI!$C$7:$C$106,$N38)) | D38: =IF($L38="","",INDEX(HSI!$D$7:$D$106,$N38)) | E38: =IF($L38="","",IF($P38=0,"TBA",IFERROR(INDEX(Grids!$C$12:$BO$111,$N38,$O38),"-"))) | F38: =IF($L38="","",INDEX(HSI!$F$7:$F$106,$N38)) | G38: =IF($L38="","",IF($P38=0,"TBA",IFERROR(INDEX(Grids!$BQ$12:$EC$111,$N38,$O38),"-"))) | H38: =IF($L38="","",SUM($G$10:$G38)) | I38: =IF($L38="","",IF(INT(($L38-INT($L38/10000000)*10000000)/1000000)=0,"Bloomberg projection",IF($P38=1,"ANNOUNCED","ANNOUNCED - amount TBA"))) | J38: =IF($L38="","",IF((OV_SWITCH="ON")*(COUNTIFS(OVR_TICKERS,INDEX(HSI!$C$7:$C$106,$N38),OVR_BASE,">=0")>0)>0,"stock overridden","")) | L38: =IFERROR(IF(SMALL(Grids!$EE$12:$GQ$111,$M$7+29)>=PEND_TO,"",SMALL(Grids!$EE$12:$GQ$111,$M$7+29)),"") | M38: =IF($L38="","",INT($L38/1000000000)) | N38: =IF($L38="","",INT(($L38-INT($L38/1000000)*1000000)/1000)) | O38: =IF($L38="","",$L38-INT($L38/1000)*1000) | P38: =IF($L38="","",INT(($L38-INT($L38/1000000000)*1000000000)/100000000))
B39: =IF($L39="","",$M39) | C39: =IF($L39="","",INDEX(HSI!$C$7:$C$106,$N39)) | D39: =IF($L39="","",INDEX(HSI!$D$7:$D$106,$N39)) | E39: =IF($L39="","",IF($P39=0,"TBA",IFERROR(INDEX(Grids!$C$12:$BO$111,$N39,$O39),"-"))) | F39: =IF($L39="","",INDEX(HSI!$F$7:$F$106,$N39)) | G39: =IF($L39="","",IF($P39=0,"TBA",IFERROR(INDEX(Grids!$BQ$12:$EC$111,$N39,$O39),"-"))) | H39: =IF($L39="","",SUM($G$10:$G39)) | I39: =IF($L39="","",IF(INT(($L39-INT($L39/10000000)*10000000)/1000000)=0,"Bloomberg projection",IF($P39=1,"ANNOUNCED","ANNOUNCED - amount TBA"))) | J39: =IF($L39="","",IF((OV_SWITCH="ON")*(COUNTIFS(OVR_TICKERS,INDEX(HSI!$C$7:$C$106,$N39),OVR_BASE,">=0")>0)>0,"stock overridden","")) | L39: =IFERROR(IF(SMALL(Grids!$EE$12:$GQ$111,$M$7+30)>=PEND_TO,"",SMALL(Grids!$EE$12:$GQ$111,$M$7+30)),"") | M39: =IF($L39="","",INT($L39/1000000000)) | N39: =IF($L39="","",INT(($L39-INT($L39/1000000)*1000000)/1000)) | O39: =IF($L39="","",$L39-INT($L39/1000)*1000) | P39: =IF($L39="","",INT(($L39-INT($L39/1000000000)*1000000000)/100000000))
B40: =IF($L40="","",$M40) | C40: =IF($L40="","",INDEX(HSI!$C$7:$C$106,$N40)) | D40: =IF($L40="","",INDEX(HSI!$D$7:$D$106,$N40)) | E40: =IF($L40="","",IF($P40=0,"TBA",IFERROR(INDEX(Grids!$C$12:$BO$111,$N40,$O40),"-"))) | F40: =IF($L40="","",INDEX(HSI!$F$7:$F$106,$N40)) | G40: =IF($L40="","",IF($P40=0,"TBA",IFERROR(INDEX(Grids!$BQ$12:$EC$111,$N40,$O40),"-"))) | H40: =IF($L40="","",SUM($G$10:$G40)) | I40: =IF($L40="","",IF(INT(($L40-INT($L40/10000000)*10000000)/1000000)=0,"Bloomberg projection",IF($P40=1,"ANNOUNCED","ANNOUNCED - amount TBA"))) | J40: =IF($L40="","",IF((OV_SWITCH="ON")*(COUNTIFS(OVR_TICKERS,INDEX(HSI!$C$7:$C$106,$N40),OVR_BASE,">=0")>0)>0,"stock overridden","")) | L40: =IFERROR(IF(SMALL(Grids!$EE$12:$GQ$111,$M$7+31)>=PEND_TO,"",SMALL(Grids!$EE$12:$GQ$111,$M$7+31)),"") | M40: =IF($L40="","",INT($L40/1000000000)) | N40: =IF($L40="","",INT(($L40-INT($L40/1000000)*1000000)/1000)) | O40: =IF($L40="","",$L40-INT($L40/1000)*1000) | P40: =IF($L40="","",INT(($L40-INT($L40/1000000000)*1000000000)/100000000))
B41: =IF($L41="","",$M41) | C41: =IF($L41="","",INDEX(HSI!$C$7:$C$106,$N41)) | D41: =IF($L41="","",INDEX(HSI!$D$7:$D$106,$N41)) | E41: =IF($L41="","",IF($P41=0,"TBA",IFERROR(INDEX(Grids!$C$12:$BO$111,$N41,$O41),"-"))) | F41: =IF($L41="","",INDEX(HSI!$F$7:$F$106,$N41)) | G41: =IF($L41="","",IF($P41=0,"TBA",IFERROR(INDEX(Grids!$BQ$12:$EC$111,$N41,$O41),"-"))) | H41: =IF($L41="","",SUM($G$10:$G41)) | I41: =IF($L41="","",IF(INT(($L41-INT($L41/10000000)*10000000)/1000000)=0,"Bloomberg projection",IF($P41=1,"ANNOUNCED","ANNOUNCED - amount TBA"))) | J41: =IF($L41="","",IF((OV_SWITCH="ON")*(COUNTIFS(OVR_TICKERS,INDEX(HSI!$C$7:$C$106,$N41),OVR_BASE,">=0")>0)>0,"stock overridden","")) | L41: =IFERROR(IF(SMALL(Grids!$EE$12:$GQ$111,$M$7+32)>=PEND_TO,"",SMALL(Grids!$EE$12:$GQ$111,$M$7+32)),"") | M41: =IF($L41="","",INT($L41/1000000000)) | N41: =IF($L41="","",INT(($L41-INT($L41/1000000)*1000000)/1000)) | O41: =IF($L41="","",$L41-INT($L41/1000)*1000) | P41: =IF($L41="","",INT(($L41-INT($L41/1000000000)*1000000000)/100000000))
B42: =IF($L42="","",$M42) | C42: =IF($L42="","",INDEX(HSI!$C$7:$C$106,$N42)) | D42: =IF($L42="","",INDEX(HSI!$D$7:$D$106,$N42)) | E42: =IF($L42="","",IF($P42=0,"TBA",IFERROR(INDEX(Grids!$C$12:$BO$111,$N42,$O42),"-"))) | F42: =IF($L42="","",INDEX(HSI!$F$7:$F$106,$N42)) | G42: =IF($L42="","",IF($P42=0,"TBA",IFERROR(INDEX(Grids!$BQ$12:$EC$111,$N42,$O42),"-"))) | H42: =IF($L42="","",SUM($G$10:$G42)) | I42: =IF($L42="","",IF(INT(($L42-INT($L42/10000000)*10000000)/1000000)=0,"Bloomberg projection",IF($P42=1,"ANNOUNCED","ANNOUNCED - amount TBA"))) | J42: =IF($L42="","",IF((OV_SWITCH="ON")*(COUNTIFS(OVR_TICKERS,INDEX(HSI!$C$7:$C$106,$N42),OVR_BASE,">=0")>0)>0,"stock overridden","")) | L42: =IFERROR(IF(SMALL(Grids!$EE$12:$GQ$111,$M$7+33)>=PEND_TO,"",SMALL(Grids!$EE$12:$GQ$111,$M$7+33)),"") | M42: =IF($L42="","",INT($L42/1000000000)) | N42: =IF($L42="","",INT(($L42-INT($L42/1000000)*1000000)/1000)) | O42: =IF($L42="","",$L42-INT($L42/1000)*1000) | P42: =IF($L42="","",INT(($L42-INT($L42/1000000000)*1000000000)/100000000))
B43: =IF($L43="","",$M43) | C43: =IF($L43="","",INDEX(HSI!$C$7:$C$106,$N43)) | D43: =IF($L43="","",INDEX(HSI!$D$7:$D$106,$N43)) | E43: =IF($L43="","",IF($P43=0,"TBA",IFERROR(INDEX(Grids!$C$12:$BO$111,$N43,$O43),"-"))) | F43: =IF($L43="","",INDEX(HSI!$F$7:$F$106,$N43)) | G43: =IF($L43="","",IF($P43=0,"TBA",IFERROR(INDEX(Grids!$BQ$12:$EC$111,$N43,$O43),"-"))) | H43: =IF($L43="","",SUM($G$10:$G43)) | I43: =IF($L43="","",IF(INT(($L43-INT($L43/10000000)*10000000)/1000000)=0,"Bloomberg projection",IF($P43=1,"ANNOUNCED","ANNOUNCED - amount TBA"))) | J43: =IF($L43="","",IF((OV_SWITCH="ON")*(COUNTIFS(OVR_TICKERS,INDEX(HSI!$C$7:$C$106,$N43),OVR_BASE,">=0")>0)>0,"stock overridden","")) | L43: =IFERROR(IF(SMALL(Grids!$EE$12:$GQ$111,$M$7+34)>=PEND_TO,"",SMALL(Grids!$EE$12:$GQ$111,$M$7+34)),"") | M43: =IF($L43="","",INT($L43/1000000000)) | N43: =IF($L43="","",INT(($L43-INT($L43/1000000)*1000000)/1000)) | O43: =IF($L43="","",$L43-INT($L43/1000)*1000) | P43: =IF($L43="","",INT(($L43-INT($L43/1000000000)*1000000000)/100000000))
...

Sheet Flow
B1: DIVIDEND FLOW - WHEN THE POINTS GO EX
B2: Year Y by ex-date. Up to the valuation date = realized, after it = still to come. Bloomberg's event view (with your cash-type rules).
B4: Year | C4: =YEAR_Y | D4: Valuation | E4: =VAL_DATE
B6: YEAR TOTALS (index points)
C7: Realized | D7: Still to come | E7: YEAR TOTAL | J7: BY MONTH (realized vs still to come) | R7: cumulative to month-end
B8: HSI | C8: =HSI!$O$5 | D8: =HSI!$P$5 | E8: =HSI!$Q$5 | J8: Month | K8: HSI realized | L8: HSI to come | M8: HSTECH realized | N8: HSTECH to come | O8: HSCEI realized | P8: HSCEI to come | R8: HSI | S8: HSTECH | T8: HSCEI
B9: HSTECH | C9: =HSTECH!$O$5 | D9: =HSTECH!$P$5 | E9: =HSTECH!$Q$5 | J9: =TEXT(DATE(YEAR_Y,1,1),"mmm") | K9: =SUMIFS($C$26:$C$395,$B$26:$B$395,">="&DATE(YEAR_Y,1,1),$B$26:$B$395,"<"&DATE(YEAR_Y+(1=12),MOD(1,12)+1,1),$B$26:$B$395,"<="&VAL_DATE) | L9: =SUMIFS($C$26:$C$395,$B$26:$B$395,">="&DATE(YEAR_Y,1,1),$B$26:$B$395,"<"&DATE(YEAR_Y+(1=12),MOD(1,12)+1,1),$B$26:$B$395,">"&VAL_DATE) | M9: =SUMIFS($D$26:$D$395,$B$26:$B$395,">="&DATE(YEAR_Y,1,1),$B$26:$B$395,"<"&DATE(YEAR_Y+(1=12),MOD(1,12)+1,1),$B$26:$B$395,"<="&VAL_DATE) | N9: =SUMIFS($D$26:$D$395,$B$26:$B$395,">="&DATE(YEAR_Y,1,1),$B$26:$B$395,"<"&DATE(YEAR_Y+(1=12),MOD(1,12)+1,1),$B$26:$B$395,">"&VAL_DATE) | O9: =SUMIFS($E$26:$E$395,$B$26:$B$395,">="&DATE(YEAR_Y,1,1),$B$26:$B$395,"<"&DATE(YEAR_Y+(1=12),MOD(1,12)+1,1),$B$26:$B$395,"<="&VAL_DATE) | P9: =SUMIFS($E$26:$E$395,$B$26:$B$395,">="&DATE(YEAR_Y,1,1),$B$26:$B$395,"<"&DATE(YEAR_Y+(1=12),MOD(1,12)+1,1),$B$26:$B$395,">"&VAL_DATE) | R9: =SUM($K$9:$L9) | S9: =SUM($M$9:$N9) | T9: =SUM($O$9:$P9)
B10: HSCEI | C10: =HSCEI!$O$5 | D10: =HSCEI!$P$5 | E10: =HSCEI!$Q$5 | J10: =TEXT(DATE(YEAR_Y,2,1),"mmm") | K10: =SUMIFS($C$26:$C$395,$B$26:$B$395,">="&DATE(YEAR_Y,2,1),$B$26:$B$395,"<"&DATE(YEAR_Y+(2=12),MOD(2,12)+1,1),$B$26:$B$395,"<="&VAL_DATE) | L10: =SUMIFS($C$26:$C$395,$B$26:$B$395,">="&DATE(YEAR_Y,2,1),$B$26:$B$395,"<"&DATE(YEAR_Y+(2=12),MOD(2,12)+1,1),$B$26:$B$395,">"&VAL_DATE) | M10: =SUMIFS($D$26:$D$395,$B$26:$B$395,">="&DATE(YEAR_Y,2,1),$B$26:$B$395,"<"&DATE(YEAR_Y+(2=12),MOD(2,12)+1,1),$B$26:$B$395,"<="&VAL_DATE) | N10: =SUMIFS($D$26:$D$395,$B$26:$B$395,">="&DATE(YEAR_Y,2,1),$B$26:$B$395,"<"&DATE(YEAR_Y+(2=12),MOD(2,12)+1,1),$B$26:$B$395,">"&VAL_DATE) | O10: =SUMIFS($E$26:$E$395,$B$26:$B$395,">="&DATE(YEAR_Y,2,1),$B$26:$B$395,"<"&DATE(YEAR_Y+(2=12),MOD(2,12)+1,1),$B$26:$B$395,"<="&VAL_DATE) | P10: =SUMIFS($E$26:$E$395,$B$26:$B$395,">="&DATE(YEAR_Y,2,1),$B$26:$B$395,"<"&DATE(YEAR_Y+(2=12),MOD(2,12)+1,1),$B$26:$B$395,">"&VAL_DATE) | R10: =SUM($K$9:$L10) | S10: =SUM($M$9:$N10) | T10: =SUM($O$9:$P10)
J11: =TEXT(DATE(YEAR_Y,3,1),"mmm") | K11: =SUMIFS($C$26:$C$395,$B$26:$B$395,">="&DATE(YEAR_Y,3,1),$B$26:$B$395,"<"&DATE(YEAR_Y+(3=12),MOD(3,12)+1,1),$B$26:$B$395,"<="&VAL_DATE) | L11: =SUMIFS($C$26:$C$395,$B$26:$B$395,">="&DATE(YEAR_Y,3,1),$B$26:$B$395,"<"&DATE(YEAR_Y+(3=12),MOD(3,12)+1,1),$B$26:$B$395,">"&VAL_DATE) | M11: =SUMIFS($D$26:$D$395,$B$26:$B$395,">="&DATE(YEAR_Y,3,1),$B$26:$B$395,"<"&DATE(YEAR_Y+(3=12),MOD(3,12)+1,1),$B$26:$B$395,"<="&VAL_DATE) | N11: =SUMIFS($D$26:$D$395,$B$26:$B$395,">="&DATE(YEAR_Y,3,1),$B$26:$B$395,"<"&DATE(YEAR_Y+(3=12),MOD(3,12)+1,1),$B$26:$B$395,">"&VAL_DATE) | O11: =SUMIFS($E$26:$E$395,$B$26:$B$395,">="&DATE(YEAR_Y,3,1),$B$26:$B$395,"<"&DATE(YEAR_Y+(3=12),MOD(3,12)+1,1),$B$26:$B$395,"<="&VAL_DATE) | P11: =SUMIFS($E$26:$E$395,$B$26:$B$395,">="&DATE(YEAR_Y,3,1),$B$26:$B$395,"<"&DATE(YEAR_Y+(3=12),MOD(3,12)+1,1),$B$26:$B$395,">"&VAL_DATE) | R11: =SUM($K$9:$L11) | S11: =SUM($M$9:$N11) | T11: =SUM($O$9:$P11)
J12: =TEXT(DATE(YEAR_Y,4,1),"mmm") | K12: =SUMIFS($C$26:$C$395,$B$26:$B$395,">="&DATE(YEAR_Y,4,1),$B$26:$B$395,"<"&DATE(YEAR_Y+(4=12),MOD(4,12)+1,1),$B$26:$B$395,"<="&VAL_DATE) | L12: =SUMIFS($C$26:$C$395,$B$26:$B$395,">="&DATE(YEAR_Y,4,1),$B$26:$B$395,"<"&DATE(YEAR_Y+(4=12),MOD(4,12)+1,1),$B$26:$B$395,">"&VAL_DATE) | M12: =SUMIFS($D$26:$D$395,$B$26:$B$395,">="&DATE(YEAR_Y,4,1),$B$26:$B$395,"<"&DATE(YEAR_Y+(4=12),MOD(4,12)+1,1),$B$26:$B$395,"<="&VAL_DATE) | N12: =SUMIFS($D$26:$D$395,$B$26:$B$395,">="&DATE(YEAR_Y,4,1),$B$26:$B$395,"<"&DATE(YEAR_Y+(4=12),MOD(4,12)+1,1),$B$26:$B$395,">"&VAL_DATE) | O12: =SUMIFS($E$26:$E$395,$B$26:$B$395,">="&DATE(YEAR_Y,4,1),$B$26:$B$395,"<"&DATE(YEAR_Y+(4=12),MOD(4,12)+1,1),$B$26:$B$395,"<="&VAL_DATE) | P12: =SUMIFS($E$26:$E$395,$B$26:$B$395,">="&DATE(YEAR_Y,4,1),$B$26:$B$395,"<"&DATE(YEAR_Y+(4=12),MOD(4,12)+1,1),$B$26:$B$395,">"&VAL_DATE) | R12: =SUM($K$9:$L12) | S12: =SUM($M$9:$N12) | T12: =SUM($O$9:$P12)
J13: =TEXT(DATE(YEAR_Y,5,1),"mmm") | K13: =SUMIFS($C$26:$C$395,$B$26:$B$395,">="&DATE(YEAR_Y,5,1),$B$26:$B$395,"<"&DATE(YEAR_Y+(5=12),MOD(5,12)+1,1),$B$26:$B$395,"<="&VAL_DATE) | L13: =SUMIFS($C$26:$C$395,$B$26:$B$395,">="&DATE(YEAR_Y,5,1),$B$26:$B$395,"<"&DATE(YEAR_Y+(5=12),MOD(5,12)+1,1),$B$26:$B$395,">"&VAL_DATE) | M13: =SUMIFS($D$26:$D$395,$B$26:$B$395,">="&DATE(YEAR_Y,5,1),$B$26:$B$395,"<"&DATE(YEAR_Y+(5=12),MOD(5,12)+1,1),$B$26:$B$395,"<="&VAL_DATE) | N13: =SUMIFS($D$26:$D$395,$B$26:$B$395,">="&DATE(YEAR_Y,5,1),$B$26:$B$395,"<"&DATE(YEAR_Y+(5=12),MOD(5,12)+1,1),$B$26:$B$395,">"&VAL_DATE) | O13: =SUMIFS($E$26:$E$395,$B$26:$B$395,">="&DATE(YEAR_Y,5,1),$B$26:$B$395,"<"&DATE(YEAR_Y+(5=12),MOD(5,12)+1,1),$B$26:$B$395,"<="&VAL_DATE) | P13: =SUMIFS($E$26:$E$395,$B$26:$B$395,">="&DATE(YEAR_Y,5,1),$B$26:$B$395,"<"&DATE(YEAR_Y+(5=12),MOD(5,12)+1,1),$B$26:$B$395,">"&VAL_DATE) | R13: =SUM($K$9:$L13) | S13: =SUM($M$9:$N13) | T13: =SUM($O$9:$P13)
J14: =TEXT(DATE(YEAR_Y,6,1),"mmm") | K14: =SUMIFS($C$26:$C$395,$B$26:$B$395,">="&DATE(YEAR_Y,6,1),$B$26:$B$395,"<"&DATE(YEAR_Y+(6=12),MOD(6,12)+1,1),$B$26:$B$395,"<="&VAL_DATE) | L14: =SUMIFS($C$26:$C$395,$B$26:$B$395,">="&DATE(YEAR_Y,6,1),$B$26:$B$395,"<"&DATE(YEAR_Y+(6=12),MOD(6,12)+1,1),$B$26:$B$395,">"&VAL_DATE) | M14: =SUMIFS($D$26:$D$395,$B$26:$B$395,">="&DATE(YEAR_Y,6,1),$B$26:$B$395,"<"&DATE(YEAR_Y+(6=12),MOD(6,12)+1,1),$B$26:$B$395,"<="&VAL_DATE) | N14: =SUMIFS($D$26:$D$395,$B$26:$B$395,">="&DATE(YEAR_Y,6,1),$B$26:$B$395,"<"&DATE(YEAR_Y+(6=12),MOD(6,12)+1,1),$B$26:$B$395,">"&VAL_DATE) | O14: =SUMIFS($E$26:$E$395,$B$26:$B$395,">="&DATE(YEAR_Y,6,1),$B$26:$B$395,"<"&DATE(YEAR_Y+(6=12),MOD(6,12)+1,1),$B$26:$B$395,"<="&VAL_DATE) | P14: =SUMIFS($E$26:$E$395,$B$26:$B$395,">="&DATE(YEAR_Y,6,1),$B$26:$B$395,"<"&DATE(YEAR_Y+(6=12),MOD(6,12)+1,1),$B$26:$B$395,">"&VAL_DATE) | R14: =SUM($K$9:$L14) | S14: =SUM($M$9:$N14) | T14: =SUM($O$9:$P14)
J15: =TEXT(DATE(YEAR_Y,7,1),"mmm") | K15: =SUMIFS($C$26:$C$395,$B$26:$B$395,">="&DATE(YEAR_Y,7,1),$B$26:$B$395,"<"&DATE(YEAR_Y+(7=12),MOD(7,12)+1,1),$B$26:$B$395,"<="&VAL_DATE) | L15: =SUMIFS($C$26:$C$395,$B$26:$B$395,">="&DATE(YEAR_Y,7,1),$B$26:$B$395,"<"&DATE(YEAR_Y+(7=12),MOD(7,12)+1,1),$B$26:$B$395,">"&VAL_DATE) | M15: =SUMIFS($D$26:$D$395,$B$26:$B$395,">="&DATE(YEAR_Y,7,1),$B$26:$B$395,"<"&DATE(YEAR_Y+(7=12),MOD(7,12)+1,1),$B$26:$B$395,"<="&VAL_DATE) | N15: =SUMIFS($D$26:$D$395,$B$26:$B$395,">="&DATE(YEAR_Y,7,1),$B$26:$B$395,"<"&DATE(YEAR_Y+(7=12),MOD(7,12)+1,1),$B$26:$B$395,">"&VAL_DATE) | O15: =SUMIFS($E$26:$E$395,$B$26:$B$395,">="&DATE(YEAR_Y,7,1),$B$26:$B$395,"<"&DATE(YEAR_Y+(7=12),MOD(7,12)+1,1),$B$26:$B$395,"<="&VAL_DATE) | P15: =SUMIFS($E$26:$E$395,$B$26:$B$395,">="&DATE(YEAR_Y,7,1),$B$26:$B$395,"<"&DATE(YEAR_Y+(7=12),MOD(7,12)+1,1),$B$26:$B$395,">"&VAL_DATE) | R15: =SUM($K$9:$L15) | S15: =SUM($M$9:$N15) | T15: =SUM($O$9:$P15)
J16: =TEXT(DATE(YEAR_Y,8,1),"mmm") | K16: =SUMIFS($C$26:$C$395,$B$26:$B$395,">="&DATE(YEAR_Y,8,1),$B$26:$B$395,"<"&DATE(YEAR_Y+(8=12),MOD(8,12)+1,1),$B$26:$B$395,"<="&VAL_DATE) | L16: =SUMIFS($C$26:$C$395,$B$26:$B$395,">="&DATE(YEAR_Y,8,1),$B$26:$B$395,"<"&DATE(YEAR_Y+(8=12),MOD(8,12)+1,1),$B$26:$B$395,">"&VAL_DATE) | M16: =SUMIFS($D$26:$D$395,$B$26:$B$395,">="&DATE(YEAR_Y,8,1),$B$26:$B$395,"<"&DATE(YEAR_Y+(8=12),MOD(8,12)+1,1),$B$26:$B$395,"<="&VAL_DATE) | N16: =SUMIFS($D$26:$D$395,$B$26:$B$395,">="&DATE(YEAR_Y,8,1),$B$26:$B$395,"<"&DATE(YEAR_Y+(8=12),MOD(8,12)+1,1),$B$26:$B$395,">"&VAL_DATE) | O16: =SUMIFS($E$26:$E$395,$B$26:$B$395,">="&DATE(YEAR_Y,8,1),$B$26:$B$395,"<"&DATE(YEAR_Y+(8=12),MOD(8,12)+1,1),$B$26:$B$395,"<="&VAL_DATE) | P16: =SUMIFS($E$26:$E$395,$B$26:$B$395,">="&DATE(YEAR_Y,8,1),$B$26:$B$395,"<"&DATE(YEAR_Y+(8=12),MOD(8,12)+1,1),$B$26:$B$395,">"&VAL_DATE) | R16: =SUM($K$9:$L16) | S16: =SUM($M$9:$N16) | T16: =SUM($O$9:$P16)
J17: =TEXT(DATE(YEAR_Y,9,1),"mmm") | K17: =SUMIFS($C$26:$C$395,$B$26:$B$395,">="&DATE(YEAR_Y,9,1),$B$26:$B$395,"<"&DATE(YEAR_Y+(9=12),MOD(9,12)+1,1),$B$26:$B$395,"<="&VAL_DATE) | L17: =SUMIFS($C$26:$C$395,$B$26:$B$395,">="&DATE(YEAR_Y,9,1),$B$26:$B$395,"<"&DATE(YEAR_Y+(9=12),MOD(9,12)+1,1),$B$26:$B$395,">"&VAL_DATE) | M17: =SUMIFS($D$26:$D$395,$B$26:$B$395,">="&DATE(YEAR_Y,9,1),$B$26:$B$395,"<"&DATE(YEAR_Y+(9=12),MOD(9,12)+1,1),$B$26:$B$395,"<="&VAL_DATE) | N17: =SUMIFS($D$26:$D$395,$B$26:$B$395,">="&DATE(YEAR_Y,9,1),$B$26:$B$395,"<"&DATE(YEAR_Y+(9=12),MOD(9,12)+1,1),$B$26:$B$395,">"&VAL_DATE) | O17: =SUMIFS($E$26:$E$395,$B$26:$B$395,">="&DATE(YEAR_Y,9,1),$B$26:$B$395,"<"&DATE(YEAR_Y+(9=12),MOD(9,12)+1,1),$B$26:$B$395,"<="&VAL_DATE) | P17: =SUMIFS($E$26:$E$395,$B$26:$B$395,">="&DATE(YEAR_Y,9,1),$B$26:$B$395,"<"&DATE(YEAR_Y+(9=12),MOD(9,12)+1,1),$B$26:$B$395,">"&VAL_DATE) | R17: =SUM($K$9:$L17) | S17: =SUM($M$9:$N17) | T17: =SUM($O$9:$P17)
J18: =TEXT(DATE(YEAR_Y,10,1),"mmm") | K18: =SUMIFS($C$26:$C$395,$B$26:$B$395,">="&DATE(YEAR_Y,10,1),$B$26:$B$395,"<"&DATE(YEAR_Y+(10=12),MOD(10,12)+1,1),$B$26:$B$395,"<="&VAL_DATE) | L18: =SUMIFS($C$26:$C$395,$B$26:$B$395,">="&DATE(YEAR_Y,10,1),$B$26:$B$395,"<"&DATE(YEAR_Y+(10=12),MOD(10,12)+1,1),$B$26:$B$395,">"&VAL_DATE) | M18: =SUMIFS($D$26:$D$395,$B$26:$B$395,">="&DATE(YEAR_Y,10,1),$B$26:$B$395,"<"&DATE(YEAR_Y+(10=12),MOD(10,12)+1,1),$B$26:$B$395,"<="&VAL_DATE) | N18: =SUMIFS($D$26:$D$395,$B$26:$B$395,">="&DATE(YEAR_Y,10,1),$B$26:$B$395,"<"&DATE(YEAR_Y+(10=12),MOD(10,12)+1,1),$B$26:$B$395,">"&VAL_DATE) | O18: =SUMIFS($E$26:$E$395,$B$26:$B$395,">="&DATE(YEAR_Y,10,1),$B$26:$B$395,"<"&DATE(YEAR_Y+(10=12),MOD(10,12)+1,1),$B$26:$B$395,"<="&VAL_DATE) | P18: =SUMIFS($E$26:$E$395,$B$26:$B$395,">="&DATE(YEAR_Y,10,1),$B$26:$B$395,"<"&DATE(YEAR_Y+(10=12),MOD(10,12)+1,1),$B$26:$B$395,">"&VAL_DATE) | R18: =SUM($K$9:$L18) | S18: =SUM($M$9:$N18) | T18: =SUM($O$9:$P18)
J19: =TEXT(DATE(YEAR_Y,11,1),"mmm") | K19: =SUMIFS($C$26:$C$395,$B$26:$B$395,">="&DATE(YEAR_Y,11,1),$B$26:$B$395,"<"&DATE(YEAR_Y+(11=12),MOD(11,12)+1,1),$B$26:$B$395,"<="&VAL_DATE) | L19: =SUMIFS($C$26:$C$395,$B$26:$B$395,">="&DATE(YEAR_Y,11,1),$B$26:$B$395,"<"&DATE(YEAR_Y+(11=12),MOD(11,12)+1,1),$B$26:$B$395,">"&VAL_DATE) | M19: =SUMIFS($D$26:$D$395,$B$26:$B$395,">="&DATE(YEAR_Y,11,1),$B$26:$B$395,"<"&DATE(YEAR_Y+(11=12),MOD(11,12)+1,1),$B$26:$B$395,"<="&VAL_DATE) | N19: =SUMIFS($D$26:$D$395,$B$26:$B$395,">="&DATE(YEAR_Y,11,1),$B$26:$B$395,"<"&DATE(YEAR_Y+(11=12),MOD(11,12)+1,1),$B$26:$B$395,">"&VAL_DATE) | O19: =SUMIFS($E$26:$E$395,$B$26:$B$395,">="&DATE(YEAR_Y,11,1),$B$26:$B$395,"<"&DATE(YEAR_Y+(11=12),MOD(11,12)+1,1),$B$26:$B$395,"<="&VAL_DATE) | P19: =SUMIFS($E$26:$E$395,$B$26:$B$395,">="&DATE(YEAR_Y,11,1),$B$26:$B$395,"<"&DATE(YEAR_Y+(11=12),MOD(11,12)+1,1),$B$26:$B$395,">"&VAL_DATE) | R19: =SUM($K$9:$L19) | S19: =SUM($M$9:$N19) | T19: =SUM($O$9:$P19)
